Workbook

Sheet README
A1: Lepas South Africa — August 2026 Media Performance Workbook
A2: Read me first. Dummy / illustrative data built to the structure of live platform exports. Not actual Lepas results.
A4: 1. WHAT THIS IS
B5: Campaign: Lepas SA — August 2026, national.
B6: Objective: Test drive bookings. That is the single conversion in this workbook.
B7: Conversion point: https://www.lepas-sa.co.za/offers → test drive booking form.
B8: Models in market: AMUR (1.5 M/T), JAVAN (1.5T DCT), PANTERA (1.5T DCT), on 0% and 10% deposit offers.
B9: Channels: Meta (Facebook + Instagram), TikTok, X, Programmatic (DV360).
B10: Total budget: R400,000 excl. VAT, 1 – 31 August 2026.
B11: Currency: South African Rand (ZAR), excluding VAT.
B13: ALL DATA IN THIS WORKBOOK IS SYNTHETIC. It is modelled on realistic South African automotive benchmarks so that it behaves like real data — but no figure here came from a live Lepas account. Replace Raw_Data with a genuine platform export and every other tab recalculates against it.
A16: 2. HOW THIS WORKBOOK IS WIRED
B17: • Raw_Data is the single source of truth. 2,551 rows at Day x Channel x Campaign x Ad Set x Creative.
B18: • Every reporting tab is built on live SUMIFS formulas pointing at Raw_Data. Nothing is pasted or hardcoded.
B19: • Assumptions is the control panel. Change a blue cell — budget, vehicle price, close rate, CPL target — and the whole workbook re-forecasts.
B20: • QA_Checks proves the tabs reconcile. Open it after any edit; every row should read PASS.
B21: • Breakdown tabs (Placements, Demographics, Location, Devices_Apps, Landing_Pages) are separate aggregates, exactly as platform exports are — you cannot cross-tab age against creative in Meta or DV360 either. They tie to the same channel totals.
A24: 3. TAB GUIDE
B25: Tab | C25: What it answers | D25: Rows | E25: Built from
B26: README | C26: You are here — definitions, method and caveats. | D26: — | E26: —
B27: Summary | C27: Headline KPIs, then performance by channel, model, audience strategy and week. | D27: ~30 | E27: SUMIFS on Raw_Data
B28: Daily_Trend | C28: Day-by-day delivery, cumulative pacing against the R400k plan, and per-channel spend / bookings / CPL. | D28: 31 | E28: SUMIFS on Raw_Data
B29: Channel_Detail | C29: Each channel cut by week, by model and by audience strategy. | D29: 64 | E29: SUMIFS on Raw_Data
B30: Campaign_AdSet | C30: Campaign roll-up, then every ad set / line item. | D30: 12+31 | E30: SUMIFS on Raw_Data
B31: Creative_Performance | C31: Every asset, its flight window, funnel efficiency and video engagement. | D31: 54 | E31: SUMIFS on Raw_Data
B32: Placements | C32: Where impressions served, indexed against each channel's own average. | D32: 22 | E32: Platform placement export
B33: Demographics | C33: Age band x gender per campaign. | D33: 216 | E33: Platform demo export
B34: Location | C34: Province and metro / non-metro, indexed to dealer density. | D34: 72 | E34: Platform geo export
B35: Devices_Apps | C35: Device and OS split, plus the app / domain inventory with viewability, IVT and brand safety. | D35: 22+25 | E35: Platform + DV360 export
B36: Landing_Pages | C36: On-site behaviour per destination URL: sessions, bounce, form starts and completions. | D36: 12 | E36: Analytics export
... B39: QA_Checks | C39: Reconciliation between every tab and Raw_Data. | D39: 24 | E39: Cross-tab formulas
A42: 4. DATA DICTIONARY
B43: Metric | C43: Definition
B44: Spend (ZAR) | C44: Media cost, excluding VAT and agency fee.
B45: Impressions | C45: Times an ad was rendered. Not unique people.
B46: Reach (sum of daily) | C46: Unique people reached, de-duplicated WITHIN a day. Summing 31 days overstates true monthly unique reach — treat as a delivery indicator, not a reach figure.
B47: Avg Daily Frequency | C47: Impressions ÷ sum of daily reach. Average times a person saw an ad per day, not across the month.
B48: Clicks (All) | C48: Every click, including profile taps, expands and reactions.
B49: Link Clicks | C49: Clicks that requested the destination URL. The number that matters.
B50: CTR (Link) | C50: Link Clicks ÷ Impressions.
...

Sheet Summary
A1: Lepas South Africa — August 2026 Media Performance
A2: Campaign objective: Test Drive Bookings | Conversion point: lepas-sa.co.za/offers | All figures in ZAR, excl. VAT | Every cell below is a live formula over Raw_Data.
A4: HEADLINE — MONTH TO DATE
B5: TOTAL MEDIA SPEND | E5: IMPRESSIONS | H5: LINK CLICKS | K5: TEST DRIVE BOOKINGS | N5: BLENDED CPL | Q5: QUALIFIED BOOKINGS | T5: COST / QUALIFIED | W5: EST. REVENUE PIPELINE
B6: =SUM(Raw_Data!$R$2:$R$2552) | E6: =SUM(Raw_Data!$S$2:$S$2552) | H6: =SUM(Raw_Data!$W$2:$W$2552) | K6: =SUM(Raw_Data!$AL$2:$AL$2552) | N6: =IFERROR(B6/K6,"") | Q6: =SUM(Raw_Data!$AO$2:$AO$2552) | T6: =IFERROR(B6/Q6,"") | W6: =SUM(Raw_Data!$AU$2:$AU$2552)
B8: =IF(N6<=Assumptions!$C$29,"ON TARGET — blended CPL of R"&TEXT(N6,"#,##0")&" is at or under the R"&TEXT(Assumptions!$C$29,"#,##0")&" KPI","OVER TARGET — blended CPL of R"&TEXT(N6,"#,##0")&" vs the R"&TEXT(Assumptions!$C$29,"#,##0")&" KPI")
B9: ="Return on media: every R1 of spend is modelled to return R"&TEXT(IFERROR(W6/B6,0),"#,##0.00")&" of vehicle revenue pipeline "&"("&TEXT(IFERROR(Q6*Assumptions!$C$26*Assumptions!$C$27,0),"#,##0")&" units at the assumed attendance and close rates)."
A11: PERFORMANCE BY CHANNEL
A12: Channel | B12: Spend (ZAR) | C12: Impressions | D12: Reach (sum of daily) | E12: Avg Daily Frequency | F12: Link Clicks | G12: CTR (Link) | H12: CPC (Link) | I12: CPM | J12: Landing Page Views | K12: LPV Rate | L12: Test Drive Bookings | M12: CVR (Booking / LPV) | N12: CPL (Cost / Booking) | O12: Qualified Leads | P12: Qualified Rate | Q12: Cost per Qualified Lead | R12: View-Through Conv. | S12: Assisted Conv. | T12: Total Attributed Conv. | U12: Est. Revenue Pipeline (ZAR) | V12: % of Spend | W12: % of Bookings
A13: Meta (FB/IG) | B13: =SUMIFS(Raw_Data!$R$2:$R$2552,Raw_Data!$D$2:$D$2552,$A13) | C13: =SUMIFS(Raw_Data!$S$2:$S$2552,Raw_Data!$D$2:$D$2552,$A13) | D13: =SUMIFS(Raw_Data!$T$2:$T$2552,Raw_Data!$D$2:$D$2552,$A13) | E13: =IFERROR(C13/D13,"") | F13: =SUMIFS(Raw_Data!$W$2:$W$2552,Raw_Data!$D$2:$D$2552,$A13) | G13: =IFERROR(F13/C13,"") | H13: =IFERROR(B13/F13,"") | I13: =IFERROR(B13/C13*1000,"") | J13: =SUMIFS(Raw_Data!$AA$2:$AA$2552,Raw_Data!$D$2:$D$2552,$A13) | K13: =IFERROR(J13/F13,"") | L13: =SUMIFS(Raw_Data!$AL$2:$AL$2552,Raw_Data!$D$2:$D$2552,$A13) | M13: =IFERROR(L13/J13,"") | N13: =IFERROR(B13/L13,"") | O13: =SUMIFS(Raw_Data!$AO$2:$AO$2552,Raw_Data!$D$2:$D$2552,$A13) | P13: =IFERROR(O13/L13,"") | Q13: =IFERROR(B13/O13,"") | R13: =SUMIFS(Raw_Data!$AR$2:$AR$2552,Raw_Data!$D$2:$D$2552,$A13) | S13: =SUMIFS(Raw_Data!$AS$2:$AS$2552,Raw_Data!$D$2:$D$2552,$A13) | T13: =L13+R13 | U13: =SUMIFS(Raw_Data!$AU$2:$AU$2552,Raw_Data!$D$2:$D$2552,$A13) | V13: =IFERROR(B13/$B$17,"") | W13: =IFERROR(L13/$L$17,"")
A14: TikTok | B14: =SUMIFS(Raw_Data!$R$2:$R$2552,Raw_Data!$D$2:$D$2552,$A14) | C14: =SUMIFS(Raw_Data!$S$2:$S$2552,Raw_Data!$D$2:$D$2552,$A14) | D14: =SUMIFS(Raw_Data!$T$2:$T$2552,Raw_Data!$D$2:$D$2552,$A14) | E14: =IFERROR(C14/D14,"") | F14: =SUMIFS(Raw_Data!$W$2:$W$2552,Raw_Data!$D$2:$D$2552,$A14) | G14: =IFERROR(F14/C14,"") | H14: =IFERROR(B14/F14,"") | I14: =IFERROR(B14/C14*1000,"") | J14: =SUMIFS(Raw_Data!$AA$2:$AA$2552,Raw_Data!$D$2:$D$2552,$A14) | K14: =IFERROR(J14/F14,"") | L14: =SUMIFS(Raw_Data!$AL$2:$AL$2552,Raw_Data!$D$2:$D$2552,$A14) | M14: =IFERROR(L14/J14,"") | N14: =IFERROR(B14/L14,"") | O14: =SUMIFS(Raw_Data!$AO$2:$AO$2552,Raw_Data!$D$2:$D$2552,$A14) | P14: =IFERROR(O14/L14,"") | Q14: =IFERROR(B14/O14,"") | R14: =SUMIFS(Raw_Data!$AR$2:$AR$2552,Raw_Data!$D$2:$D$2552,$A14) | S14: =SUMIFS(Raw_Data!$AS$2:$AS$2552,Raw_Data!$D$2:$D$2552,$A14) | T14: =L14+R14 | U14: =SUMIFS(Raw_Data!$AU$2:$AU$2552,Raw_Data!$D$2:$D$2552,$A14) | V14: =IFERROR(B14/$B$17,"") | W14: =IFERROR(L14/$L$17,"")
A15: X | B15: =SUMIFS(Raw_Data!$R$2:$R$2552,Raw_Data!$D$2:$D$2552,$A15) | C15: =SUMIFS(Raw_Data!$S$2:$S$2552,Raw_Data!$D$2:$D$2552,$A15) | D15: =SUMIFS(Raw_Data!$T$2:$T$2552,Raw_Data!$D$2:$D$2552,$A15) | E15: =IFERROR(C15/D15,"") | F15: =SUMIFS(Raw_Data!$W$2:$W$2552,Raw_Data!$D$2:$D$2552,$A15) | G15: =IFERROR(F15/C15,"") | H15: =IFERROR(B15/F15,"") | I15: =IFERROR(B15/C15*1000,"") | J15: =SUMIFS(Raw_Data!$AA$2:$AA$2552,Raw_Data!$D$2:$D$2552,$A15) | K15: =IFERROR(J15/F15,"") | L15: =SUMIFS(Raw_Data!$AL$2:$AL$2552,Raw_Data!$D$2:$D$2552,$A15) | M15: =IFERROR(L15/J15,"") | N15: =IFERROR(B15/L15,"") | O15: =SUMIFS(Raw_Data!$AO$2:$AO$2552,Raw_Data!$D$2:$D$2552,$A15) | P15: =IFERROR(O15/L15,"") | Q15: =IFERROR(B15/O15,"") | R15: =SUMIFS(Raw_Data!$AR$2:$AR$2552,Raw_Data!$D$2:$D$2552,$A15) | S15: =SUMIFS(Raw_Data!$AS$2:$AS$2552,Raw_Data!$D$2:$D$2552,$A15) | T15: =L15+R15 | U15: =SUMIFS(Raw_Data!$AU$2:$AU$2552,Raw_Data!$D$2:$D$2552,$A15) | V15: =IFERROR(B15/$B$17,"") | W15: =IFERROR(L15/$L$17,"")
A16: Programmatic | B16: =SUMIFS(Raw_Data!$R$2:$R$2552,Raw_Data!$D$2:$D$2552,$A16) | C16: =SUMIFS(Raw_Data!$S$2:$S$2552,Raw_Data!$D$2:$D$2552,$A16) | D16: =SUMIFS(Raw_Data!$T$2:$T$2552,Raw_Data!$D$2:$D$2552,$A16) | E16: =IFERROR(C16/D16,"") | F16: =SUMIFS(Raw_Data!$W$2:$W$2552,Raw_Data!$D$2:$D$2552,$A16) | G16: =IFERROR(F16/C16,"") | H16: =IFERROR(B16/F16,"") | I16: =IFERROR(B16/C16*1000,"") | J16: =SUMIFS(Raw_Data!$AA$2:$AA$2552,Raw_Data!$D$2:$D$2552,$A16) | K16: =IFERROR(J16/F16,"") | L16: =SUMIFS(Raw_Data!$AL$2:$AL$2552,Raw_Data!$D$2:$D$2552,$A16) | M16: =IFERROR(L16/J16,"") | N16: =IFERROR(B16/L16,"") | O16: =SUMIFS(Raw_Data!$AO$2:$AO$2552,Raw_Data!$D$2:$D$2552,$A16) | P16: =IFERROR(O16/L16,"") | Q16: =IFERROR(B16/O16,"") | R16: =SUMIFS(Raw_Data!$AR$2:$AR$2552,Raw_Data!$D$2:$D$2552,$A16) | S16: =SUMIFS(Raw_Data!$AS$2:$AS$2552,Raw_Data!$D$2:$D$2552,$A16) | T16: =L16+R16 | U16: =SUMIFS(Raw_Data!$AU$2:$AU$2552,Raw_Data!$D$2:$D$2552,$A16) | V16: =IFERROR(B16/$B$17,"") | W16: =IFERROR(L16/$L$17,"")
A17: TOTAL / BLENDED | E17: =IFERROR(C17/D17,"") | G17: =IFERROR(F17/C17,"") | H17: =IFERROR(B17/F17,"") | I17: =IFERROR(B17/C17*1000,"") | K17: =IFERROR(J17/F17,"") | M17: =IFERROR(L17/J17,"") | N17: =IFERROR(B17/L17,"") | P17: =IFERROR(O17/L17,"") | Q17: =IFERROR(B17/O17,"") | T17: =L17+R17 | V17: =IFERROR(B17/$B$17,"") | W17: =IFERROR(L17/$L$17,"")
A19: PERFORMANCE BY MODEL
A20: Model | B20: Spend (ZAR) | C20: Impressions | D20: Reach (sum of daily) | E20: Avg Daily Frequency | F20: Link Clicks | G20: CTR (Link) | H20: CPC (Link) | I20: CPM | J20: Landing Page Views | K20: LPV Rate | L20: Test Drive Bookings | M20: CVR (Booking / LPV) | N20: CPL (Cost / Booking) | O20: Qualified Leads | P20: Qualified Rate | Q20: Cost per Qualified Lead | R20: View-Through Conv. | S20: Assisted Conv. | T20: Total Attributed Conv. | U20: Est. Revenue Pipeline (ZAR) | V20: % of Spend | W20: % of Bookings
A21: AMUR | B21: =SUMIFS(Raw_Data!$R$2:$R$2552,Raw_Data!$H$2:$H$2552,$A21) | C21: =SUMIFS(Raw_Data!$S$2:$S$2552,Raw_Data!$H$2:$H$2552,$A21) | D21: =SUMIFS(Raw_Data!$T$2:$T$2552,Raw_Data!$H$2:$H$2552,$A21) | E21: =IFERROR(C21/D21,"") | F21: =SUMIFS(Raw_Data!$W$2:$W$2552,Raw_Data!$H$2:$H$2552,$A21) | G21: =IFERROR(F21/C21,"") | H21: =IFERROR(B21/F21,"") | I21: =IFERROR(B21/C21*1000,"") | J21: =SUMIFS(Raw_Data!$AA$2:$AA$2552,Raw_Data!$H$2:$H$2552,$A21) | K21: =IFERROR(J21/F21,"") | L21: =SUMIFS(Raw_Data!$AL$2:$AL$2552,Raw_Data!$H$2:$H$2552,$A21) | M21: =IFERROR(L21/J21,"") | N21: =IFERROR(B21/L21,"") | O21: =SUMIFS(Raw_Data!$AO$2:$AO$2552,Raw_Data!$H$2:$H$2552,$A21) | P21: =IFERROR(O21/L21,"") | Q21: =IFERROR(B21/O21,"") | R21: =SUMIFS(Raw_Data!$AR$2:$AR$2552,Raw_Data!$H$2:$H$2552,$A21) | S21: =SUMIFS(Raw_Data!$AS$2:$AS$2552,Raw_Data!$H$2:$H$2552,$A21) | T21: =L21+R21 | U21: =SUMIFS(Raw_Data!$AU$2:$AU$2552,Raw_Data!$H$2:$H$2552,$A21) | V21: =IFERROR(B21/$B$17,"") | W21: =IFERROR(L21/$L$17,"")
A22: JAVAN | B22: =SUMIFS(Raw_Data!$R$2:$R$2552,Raw_Data!$H$2:$H$2552,$A22) | C22: =SUMIFS(Raw_Data!$S$2:$S$2552,Raw_Data!$H$2:$H$2552,$A22) | D22: =SUMIFS(Raw_Data!$T$2:$T$2552,Raw_Data!$H$2:$H$2552,$A22) | E22: =IFERROR(C22/D22,"") | F22: =SUMIFS(Raw_Data!$W$2:$W$2552,Raw_Data!$H$2:$H$2552,$A22) | G22: =IFERROR(F22/C22,"") | H22: =IFERROR(B22/F22,"") | I22: =IFERROR(B22/C22*1000,"") | J22: =SUMIFS(Raw_Data!$AA$2:$AA$2552,Raw_Data!$H$2:$H$2552,$A22) | K22: =IFERROR(J22/F22,"") | L22: =SUMIFS(Raw_Data!$AL$2:$AL$2552,Raw_Data!$H$2:$H$2552,$A22) | M22: =IFERROR(L22/J22,"") | N22: =IFERROR(B22/L22,"") | O22: =SUMIFS(Raw_Data!$AO$2:$AO$2552,Raw_Data!$H$2:$H$2552,$A22) | P22: =IFERROR(O22/L22,"") | Q22: =IFERROR(B22/O22,"") | R22: =SUMIFS(Raw_Data!$AR$2:$AR$2552,Raw_Data!$H$2:$H$2552,$A22) | S22: =SUMIFS(Raw_Data!$AS$2:$AS$2552,Raw_Data!$H$2:$H$2552,$A22) | T22: =L22+R22 | U22: =SUMIFS(Raw_Data!$AU$2:$AU$2552,Raw_Data!$H$2:$H$2552,$A22) | V22: =IFERROR(B22/$B$17,"") | W22: =IFERROR(L22/$L$17,"")
A23: PANTERA | B23: =SUMIFS(Raw_Data!$R$2:$R$2552,Raw_Data!$H$2:$H$2552,$A23) | C23: =SUMIFS(Raw_Data!$S$2:$S$2552,Raw_Data!$H$2:$H$2552,$A23) | D23: =SUMIFS(Raw_Data!$T$2:$T$2552,Raw_Data!$H$2:$H$2552,$A23) | E23: =IFERROR(C23/D23,"") | F23: =SUMIFS(Raw_Data!$W$2:$W$2552,Raw_Data!$H$2:$H$2552,$A23) | G23: =IFERROR(F23/C23,"") | H23: =IFERROR(B23/F23,"") | I23: =IFERROR(B23/C23*1000,"") | J23: =SUMIFS(Raw_Data!$AA$2:$AA$2552,Raw_Data!$H$2:$H$2552,$A23) | K23: =IFERROR(J23/F23,"") | L23: =SUMIFS(Raw_Data!$AL$2:$AL$2552,Raw_Data!$H$2:$H$2552,$A23) | M23: =IFERROR(L23/J23,"") | N23: =IFERROR(B23/L23,"") | O23: =SUMIFS(Raw_Data!$AO$2:$AO$2552,Raw_Data!$H$2:$H$2552,$A23) | P23: =IFERROR(O23/L23,"") | Q23: =IFERROR(B23/O23,"") | R23: =SUMIFS(Raw_Data!$AR$2:$AR$2552,Raw_Data!$H$2:$H$2552,$A23) | S23: =SUMIFS(Raw_Data!$AS$2:$AS$2552,Raw_Data!$H$2:$H$2552,$A23) | T23: =L23+R23 | U23: =SUMIFS(Raw_Data!$AU$2:$AU$2552,Raw_Data!$H$2:$H$2552,$A23) | V23: =IFERROR(B23/$B$17,"") | W23: =IFERROR(L23/$L$17,"")
A24: Range | B24: =SUMIFS(Raw_Data!$R$2:$R$2552,Raw_Data!$H$2:$H$2552,$A24) | C24: =SUMIFS(Raw_Data!$S$2:$S$2552,Raw_Data!$H$2:$H$2552,$A24) | D24: =SUMIFS(Raw_Data!$T$2:$T$2552,Raw_Data!$H$2:$H$2552,$A24) | E24: =IFERROR(C24/D24,"") | F24: =SUMIFS(Raw_Data!$W$2:$W$2552,Raw_Data!$H$2:$H$2552,$A24) | G24: =IFERROR(F24/C24,"") | H24: =IFERROR(B24/F24,"") | I24: =IFERROR(B24/C24*1000,"") | J24: =SUMIFS(Raw_Data!$AA$2:$AA$2552,Raw_Data!$H$2:$H$2552,$A24) | K24: =IFERROR(J24/F24,"") | L24: =SUMIFS(Raw_Data!$AL$2:$AL$2552,Raw_Data!$H$2:$H$2552,$A24) | M24: =IFERROR(L24/J24,"") | N24: =IFERROR(B24/L24,"") | O24: =SUMIFS(Raw_Data!$AO$2:$AO$2552,Raw_Data!$H$2:$H$2552,$A24) | P24: =IFERROR(O24/L24,"") | Q24: =IFERROR(B24/O24,"") | R24: =SUMIFS(Raw_Data!$AR$2:$AR$2552,Raw_Data!$H$2:$H$2552,$A24) | S24: =SUMIFS(Raw_Data!$AS$2:$AS$2552,Raw_Data!$H$2:$H$2552,$A24) | T24: =L24+R24 | U24: =SUMIFS(Raw_Data!$AU$2:$AU$2552,Raw_Data!$H$2:$H$2552,$A24) | V24: =IFERROR(B24/$B$17,"") | W24: =IFERROR(L24/$L$17,"")
A25: TOTAL | E25: =IFERROR(C25/D25,"") | G25: =IFERROR(F25/C25,"") | H25: =IFERROR(B25/F25,"") | I25: =IFERROR(B25/C25*1000,"") | K25: =IFERROR(J25/F25,"") | M25: =IFERROR(L25/J25,"") | N25: =IFERROR(B25/L25,"") | P25: =IFERROR(O25/L25,"") | Q25: =IFERROR(B25/O25,"") | T25: =L25+R25 | V25: =IFERROR(B25/$B$17,"") | W25: =IFERROR(L25/$L$17,"")
A27: PERFORMANCE BY AUDIENCE STRATEGY
A28: Audience Type | B28: Spend (ZAR) | C28: Impressions | D28: Reach (sum of daily) | E28: Avg Daily Frequency | F28: Link Clicks | G28: CTR (Link) | H28: CPC (Link) | I28: CPM | J28: Landing Page Views | K28: LPV Rate | L28: Test Drive Bookings | M28: CVR (Booking / LPV) | N28: CPL (Cost / Booking) | O28: Qualified Leads | P28: Qualified Rate | Q28: Cost per Qualified Lead | R28: View-Through Conv. | S28: Assisted Conv. | T28: Total Attributed Conv. | U28: Est. Revenue Pipeline (ZAR) | V28: % of Spend | W28: % of Bookings
A29: Contextual | B29: =SUMIFS(Raw_Data!$R$2:$R$2552,Raw_Data!$K$2:$K$2552,$A29) | C29: =SUMIFS(Raw_Data!$S$2:$S$2552,Raw_Data!$K$2:$K$2552,$A29) | D29: =SUMIFS(Raw_Data!$T$2:$T$2552,Raw_Data!$K$2:$K$2552,$A29) | E29: =IFERROR(C29/D29,"") | F29: =SUMIFS(Raw_Data!$W$2:$W$2552,Raw_Data!$K$2:$K$2552,$A29) | G29: =IFERROR(F29/C29,"") | H29: =IFERROR(B29/F29,"") | I29: =IFERROR(B29/C29*1000,"") | J29: =SUMIFS(Raw_Data!$AA$2:$AA$2552,Raw_Data!$K$2:$K$2552,$A29) | K29: =IFERROR(J29/F29,"") | L29: =SUMIFS(Raw_Data!$AL$2:$AL$2552,Raw_Data!$K$2:$K$2552,$A29) | M29: =IFERROR(L29/J29,"") | N29: =IFERROR(B29/L29,"") | O29: =SUMIFS(Raw_Data!$AO$2:$AO$2552,Raw_Data!$K$2:$K$2552,$A29) | P29: =IFERROR(O29/L29,"") | Q29: =IFERROR(B29/O29,"") | R29: =SUMIFS(Raw_Data!$AR$2:$AR$2552,Raw_Data!$K$2:$K$2552,$A29) | S29: =SUMIFS(Raw_Data!$AS$2:$AS$2552,Raw_Data!$K$2:$K$2552,$A29) | T29: =L29+R29 | U29: =SUMIFS(Raw_Data!$AU$2:$AU$2552,Raw_Data!$K$2:$K$2552,$A29) | V29: =IFERROR(B29/$B$17,"") | W29: =IFERROR(L29/$L$17,"")
A30: In-Market | B30: =SUMIFS(Raw_Data!$R$2:$R$2552,Raw_Data!$K$2:$K$2552,$A30) | C30: =SUMIFS(Raw_Data!$S$2:$S$2552,Raw_Data!$K$2:$K$2552,$A30) | D30: =SUMIFS(Raw_Data!$T$2:$T$2552,Raw_Data!$K$2:$K$2552,$A30) | E30: =IFERROR(C30/D30,"") | F30: =SUMIFS(Raw_Data!$W$2:$W$2552,Raw_Data!$K$2:$K$2552,$A30) | G30: =IFERROR(F30/C30,"") | H30: =IFERROR(B30/F30,"") | I30: =IFERROR(B30/C30*1000,"") | J30: =SUMIFS(Raw_Data!$AA$2:$AA$2552,Raw_Data!$K$2:$K$2552,$A30) | K30: =IFERROR(J30/F30,"") | L30: =SUMIFS(Raw_Data!$AL$2:$AL$2552,Raw_Data!$K$2:$K$2552,$A30) | M30: =IFERROR(L30/J30,"") | N30: =IFERROR(B30/L30,"") | O30: =SUMIFS(Raw_Data!$AO$2:$AO$2552,Raw_Data!$K$2:$K$2552,$A30) | P30: =IFERROR(O30/L30,"") | Q30: =IFERROR(B30/O30,"") | R30: =SUMIFS(Raw_Data!$AR$2:$AR$2552,Raw_Data!$K$2:$K$2552,$A30) | S30: =SUMIFS(Raw_Data!$AS$2:$AS$2552,Raw_Data!$K$2:$K$2552,$A30) | T30: =L30+R30 | U30: =SUMIFS(Raw_Data!$AU$2:$AU$2552,Raw_Data!$K$2:$K$2552,$A30) | V30: =IFERROR(B30/$B$17,"") | W30: =IFERROR(L30/$L$17,"")
A31: Interest | B31: =SUMIFS(Raw_Data!$R$2:$R$2552,Raw_Data!$K$2:$K$2552,$A31) | C31: =SUMIFS(Raw_Data!$S$2:$S$2552,Raw_Data!$K$2:$K$2552,$A31) | D31: =SUMIFS(Raw_Data!$T$2:$T$2552,Raw_Data!$K$2:$K$2552,$A31) | E31: =IFERROR(C31/D31,"") | F31: =SUMIFS(Raw_Data!$W$2:$W$2552,Raw_Data!$K$2:$K$2552,$A31) | G31: =IFERROR(F31/C31,"") | H31: =IFERROR(B31/F31,"") | I31: =IFERROR(B31/C31*1000,"") | J31: =SUMIFS(Raw_Data!$AA$2:$AA$2552,Raw_Data!$K$2:$K$2552,$A31) | K31: =IFERROR(J31/F31,"") | L31: =SUMIFS(Raw_Data!$AL$2:$AL$2552,Raw_Data!$K$2:$K$2552,$A31) | M31: =IFERROR(L31/J31,"") | N31: =IFERROR(B31/L31,"") | O31: =SUMIFS(Raw_Data!$AO$2:$AO$2552,Raw_Data!$K$2:$K$2552,$A31) | P31: =IFERROR(O31/L31,"") | Q31: =IFERROR(B31/O31,"") | R31: =SUMIFS(Raw_Data!$AR$2:$AR$2552,Raw_Data!$K$2:$K$2552,$A31) | S31: =SUMIFS(Raw_Data!$AS$2:$AS$2552,Raw_Data!$K$2:$K$2552,$A31) | T31: =L31+R31 | U31: =SUMIFS(Raw_Data!$AU$2:$AU$2552,Raw_Data!$K$2:$K$2552,$A31) | V31: =IFERROR(B31/$B$17,"") | W31: =IFERROR(L31/$L$17,"")
A32: Lookalike | B32: =SUMIFS(Raw_Data!$R$2:$R$2552,Raw_Data!$K$2:$K$2552,$A32) | C32: =SUMIFS(Raw_Data!$S$2:$S$2552,Raw_Data!$K$2:$K$2552,$A32) | D32: =SUMIFS(Raw_Data!$T$2:$T$2552,Raw_Data!$K$2:$K$2552,$A32) | E32: =IFERROR(C32/D32,"") | F32: =SUMIFS(Raw_Data!$W$2:$W$2552,Raw_Data!$K$2:$K$2552,$A32) | G32: =IFERROR(F32/C32,"") | H32: =IFERROR(B32/F32,"") | I32: =IFERROR(B32/C32*1000,"") | J32: =SUMIFS(Raw_Data!$AA$2:$AA$2552,Raw_Data!$K$2:$K$2552,$A32) | K32: =IFERROR(J32/F32,"") | L32: =SUMIFS(Raw_Data!$AL$2:$AL$2552,Raw_Data!$K$2:$K$2552,$A32) | M32: =IFERROR(L32/J32,"") | N32: =IFERROR(B32/L32,"") | O32: =SUMIFS(Raw_Data!$AO$2:$AO$2552,Raw_Data!$K$2:$K$2552,$A32) | P32: =IFERROR(O32/L32,"") | Q32: =IFERROR(B32/O32,"") | R32: =SUMIFS(Raw_Data!$AR$2:$AR$2552,Raw_Data!$K$2:$K$2552,$A32) | S32: =SUMIFS(Raw_Data!$AS$2:$AS$2552,Raw_Data!$K$2:$K$2552,$A32) | T32: =L32+R32 | U32: =SUMIFS(Raw_Data!$AU$2:$AU$2552,Raw_Data!$K$2:$K$2552,$A32) | V32: =IFERROR(B32/$B$17,"") | W32: =IFERROR(L32/$L$17,"")
A33: Prospecting | B33: =SUMIFS(Raw_Data!$R$2:$R$2552,Raw_Data!$K$2:$K$2552,$A33) | C33: =SUMIFS(Raw_Data!$S$2:$S$2552,Raw_Data!$K$2:$K$2552,$A33) | D33: =SUMIFS(Raw_Data!$T$2:$T$2552,Raw_Data!$K$2:$K$2552,$A33) | E33: =IFERROR(C33/D33,"") | F33: =SUMIFS(Raw_Data!$W$2:$W$2552,Raw_Data!$K$2:$K$2552,$A33) | G33: =IFERROR(F33/C33,"") | H33: =IFERROR(B33/F33,"") | I33: =IFERROR(B33/C33*1000,"") | J33: =SUMIFS(Raw_Data!$AA$2:$AA$2552,Raw_Data!$K$2:$K$2552,$A33) | K33: =IFERROR(J33/F33,"") | L33: =SUMIFS(Raw_Data!$AL$2:$AL$2552,Raw_Data!$K$2:$K$2552,$A33) | M33: =IFERROR(L33/J33,"") | N33: =IFERROR(B33/L33,"") | O33: =SUMIFS(Raw_Data!$AO$2:$AO$2552,Raw_Data!$K$2:$K$2552,$A33) | P33: =IFERROR(O33/L33,"") | Q33: =IFERROR(B33/O33,"") | R33: =SUMIFS(Raw_Data!$AR$2:$AR$2552,Raw_Data!$K$2:$K$2552,$A33) | S33: =SUMIFS(Raw_Data!$AS$2:$AS$2552,Raw_Data!$K$2:$K$2552,$A33) | T33: =L33+R33 | U33: =SUMIFS(Raw_Data!$AU$2:$AU$2552,Raw_Data!$K$2:$K$2552,$A33) | V33: =IFERROR(B33/$B$17,"") | W33: =IFERROR(L33/$L$17,"")
A34: Retargeting | B34: =SUMIFS(Raw_Data!$R$2:$R$2552,Raw_Data!$K$2:$K$2552,$A34) | C34: =SUMIFS(Raw_Data!$S$2:$S$2552,Raw_Data!$K$2:$K$2552,$A34) | D34: =SUMIFS(Raw_Data!$T$2:$T$2552,Raw_Data!$K$2:$K$2552,$A34) | E34: =IFERROR(C34/D34,"") | F34: =SUMIFS(Raw_Data!$W$2:$W$2552,Raw_Data!$K$2:$K$2552,$A34) | G34: =IFERROR(F34/C34,"") | H34: =IFERROR(B34/F34,"") | I34: =IFERROR(B34/C34*1000,"") | J34: =SUMIFS(Raw_Data!$AA$2:$AA$2552,Raw_Data!$K$2:$K$2552,$A34) | K34: =IFERROR(J34/F34,"") | L34: =SUMIFS(Raw_Data!$AL$2:$AL$2552,Raw_Data!$K$2:$K$2552,$A34) | M34: =IFERROR(L34/J34,"") | N34: =IFERROR(B34/L34,"") | O34: =SUMIFS(Raw_Data!$AO$2:$AO$2552,Raw_Data!$K$2:$K$2552,$A34) | P34: =IFERROR(O34/L34,"") | Q34: =IFERROR(B34/O34,"") | R34: =SUMIFS(Raw_Data!$AR$2:$AR$2552,Raw_Data!$K$2:$K$2552,$A34) | S34: =SUMIFS(Raw_Data!$AS$2:$AS$2552,Raw_Data!$K$2:$K$2552,$A34) | T34: =L34+R34 | U34: =SUMIFS(Raw_Data!$AU$2:$AU$2552,Raw_Data!$K$2:$K$2552,$A34) | V34: =IFERROR(B34/$B$17,"") | W34: =IFERROR(L34/$L$17,"")
A35: TOTAL | E35: =IFERROR(C35/D35,"") | G35: =IFERROR(F35/C35,"") | H35: =IFERROR(B35/F35,"") | I35: =IFERROR(B35/C35*1000,"") | K35: =IFERROR(J35/F35,"") | M35: =IFERROR(L35/J35,"") | N35: =IFERROR(B35/L35,"") | P35: =IFERROR(O35/L35,"") | Q35: =IFERROR(B35/O35,"") | T35: =L35+R35 | V35: =IFERROR(B35/$B$17,"") | W35: =IFERROR(L35/$L$17,"")
A37: PERFORMANCE BY WEEK
A38: ISO Week | B38: Spend (ZAR) | C38: Impressions | D38: Reach (sum of daily) | E38: Avg Daily Frequency | F38: Link Clicks | G38: CTR (Link) | H38: CPC (Link) | I38: CPM | J38: Landing Page Views | K38: LPV Rate | L38: Test Drive Bookings | M38: CVR (Booking / LPV) | N38: CPL (Cost / Booking) | O38: Qualified Leads | P38: Qualified Rate | Q38: Cost per Qualified Lead | R38: View-Through Conv. | S38: Assisted Conv. | T38: Total Attributed Conv. | U38: Est. Revenue Pipeline (ZAR) | V38: % of Spend | W38: % of Bookings
A39: Wk 31 | B39: =SUMIFS(Raw_Data!$R$2:$R$2552,Raw_Data!$B$2:$B$2552,$A39) | C39: =SUMIFS(Raw_Data!$S$2:$S$2552,Raw_Data!$B$2:$B$2552,$A39) | D39: =SUMIFS(Raw_Data!$T$2:$T$2552,Raw_Data!$B$2:$B$2552,$A39) | E39: =IFERROR(C39/D39,"") | F39: =SUMIFS(Raw_Data!$W$2:$W$2552,Raw_Data!$B$2:$B$2552,$A39) | G39: =IFERROR(F39/C39,"") | H39: =IFERROR(B39/F39,"") | I39: =IFERROR(B39/C39*1000,"") | J39: =SUMIFS(Raw_Data!$AA$2:$AA$2552,Raw_Data!$B$2:$B$2552,$A39) | K39: =IFERROR(J39/F39,"") | L39: =SUMIFS(Raw_Data!$AL$2:$AL$2552,Raw_Data!$B$2:$B$2552,$A39) | M39: =IFERROR(L39/J39,"") | N39: =IFERROR(B39/L39,"") | O39: =SUMIFS(Raw_Data!$AO$2:$AO$2552,Raw_Data!$B$2:$B$2552,$A39) | P39: =IFERROR(O39/L39,"") | Q39: =IFERROR(B39/O39,"") | R39: =SUMIFS(Raw_Data!$AR$2:$AR$2552,Raw_Data!$B$2:$B$2552,$A39) | S39: =SUMIFS(Raw_Data!$AS$2:$AS$2552,Raw_Data!$B$2:$B$2552,$A39) | T39: =L39+R39 | U39: =SUMIFS(Raw_Data!$AU$2:$AU$2552,Raw_Data!$B$2:$B$2552,$A39) | V39: =IFERROR(B39/$B$17,"") | W39: =IFERROR(L39/$L$17,"")
A40: Wk 32 | B40: =SUMIFS(Raw_Data!$R$2:$R$2552,Raw_Data!$B$2:$B$2552,$A40) | C40: =SUMIFS(Raw_Data!$S$2:$S$2552,Raw_Data!$B$2:$B$2552,$A40) | D40: =SUMIFS(Raw_Data!$T$2:$T$2552,Raw_Data!$B$2:$B$2552,$A40) | E40: =IFERROR(C40/D40,"") | F40: =SUMIFS(Raw_Data!$W$2:$W$2552,Raw_Data!$B$2:$B$2552,$A40) | G40: =IFERROR(F40/C40,"") | H40: =IFERROR(B40/F40,"") | I40: =IFERROR(B40/C40*1000,"") | J40: =SUMIFS(Raw_Data!$AA$2:$AA$2552,Raw_Data!$B$2:$B$2552,$A40) | K40: =IFERROR(J40/F40,"") | L40: =SUMIFS(Raw_Data!$AL$2:$AL$2552,Raw_Data!$B$2:$B$2552,$A40) | M40: =IFERROR(L40/J40,"") | N40: =IFERROR(B40/L40,"") | O40: =SUMIFS(Raw_Data!$AO$2:$AO$2552,Raw_Data!$B$2:$B$2552,$A40) | P40: =IFERROR(O40/L40,"") | Q40: =IFERROR(B40/O40,"") | R40: =SUMIFS(Raw_Data!$AR$2:$AR$2552,Raw_Data!$B$2:$B$2552,$A40) | S40: =SUMIFS(Raw_Data!$AS$2:$AS$2552,Raw_Data!$B$2:$B$2552,$A40) | T40: =L40+R40 | U40: =SUMIFS(Raw_Data!$AU$2:$AU$2552,Raw_Data!$B$2:$B$2552,$A40) | V40: =IFERROR(B40/$B$17,"") | W40: =IFERROR(L40/$L$17,"")
A41: Wk 33 | B41: =SUMIFS(Raw_Data!$R$2:$R$2552,Raw_Data!$B$2:$B$2552,$A41) | C41: =SUMIFS(Raw_Data!$S$2:$S$2552,Raw_Data!$B$2:$B$2552,$A41) | D41: =SUMIFS(Raw_Data!$T$2:$T$2552,Raw_Data!$B$2:$B$2552,$A41) | E41: =IFERROR(C41/D41,"") | F41: =SUMIFS(Raw_Data!$W$2:$W$2552,Raw_Data!$B$2:$B$2552,$A41) | G41: =IFERROR(F41/C41,"") | H41: =IFERROR(B41/F41,"") | I41: =IFERROR(B41/C41*1000,"") | J41: =SUMIFS(Raw_Data!$AA$2:$AA$2552,Raw_Data!$B$2:$B$2552,$A41) | K41: =IFERROR(J41/F41,"") | L41: =SUMIFS(Raw_Data!$AL$2:$AL$2552,Raw_Data!$B$2:$B$2552,$A41) | M41: =IFERROR(L41/J41,"") | N41: =IFERROR(B41/L41,"") | O41: =SUMIFS(Raw_Data!$AO$2:$AO$2552,Raw_Data!$B$2:$B$2552,$A41) | P41: =IFERROR(O41/L41,"") | Q41: =IFERROR(B41/O41,"") | R41: =SUMIFS(Raw_Data!$AR$2:$AR$2552,Raw_Data!$B$2:$B$2552,$A41) | S41: =SUMIFS(Raw_Data!$AS$2:$AS$2552,Raw_Data!$B$2:$B$2552,$A41) | T41: =L41+R41 | U41: =SUMIFS(Raw_Data!$AU$2:$AU$2552,Raw_Data!$B$2:$B$2552,$A41) | V41: =IFERROR(B41/$B$17,"") | W41: =IFERROR(L41/$L$17,"")
A42: Wk 34 | B42: =SUMIFS(Raw_Data!$R$2:$R$2552,Raw_Data!$B$2:$B$2552,$A42) | C42: =SUMIFS(Raw_Data!$S$2:$S$2552,Raw_Data!$B$2:$B$2552,$A42) | D42: =SUMIFS(Raw_Data!$T$2:$T$2552,Raw_Data!$B$2:$B$2552,$A42) | E42: =IFERROR(C42/D42,"") | F42: =SUMIFS(Raw_Data!$W$2:$W$2552,Raw_Data!$B$2:$B$2552,$A42) | G42: =IFERROR(F42/C42,"") | H42: =IFERROR(B42/F42,"") | I42: =IFERROR(B42/C42*1000,"") | J42: =SUMIFS(Raw_Data!$AA$2:$AA$2552,Raw_Data!$B$2:$B$2552,$A42) | K42: =IFERROR(J42/F42,"") | L42: =SUMIFS(Raw_Data!$AL$2:$AL$2552,Raw_Data!$B$2:$B$2552,$A42) | M42: =IFERROR(L42/J42,"") | N42: =IFERROR(B42/L42,"") | O42: =SUMIFS(Raw_Data!$AO$2:$AO$2552,Raw_Data!$B$2:$B$2552,$A42) | P42: =IFERROR(O42/L42,"") | Q42: =IFERROR(B42/O42,"") | R42: =SUMIFS(Raw_Data!$AR$2:$AR$2552,Raw_Data!$B$2:$B$2552,$A42) | S42: =SUMIFS(Raw_Data!$AS$2:$AS$2552,Raw_Data!$B$2:$B$2552,$A42) | T42: =L42+R42 | U42: =SUMIFS(Raw_Data!$AU$2:$AU$2552,Raw_Data!$B$2:$B$2552,$A42) | V42: =IFERROR(B42/$B$17,"") | W42: =IFERROR(L42/$L$17,"")
A43: Wk 35 | B43: =SUMIFS(Raw_Data!$R$2:$R$2552,Raw_Data!$B$2:$B$2552,$A43) | C43: =SUMIFS(Raw_Data!$S$2:$S$2552,Raw_Data!$B$2:$B$2552,$A43) | D43: =SUMIFS(Raw_Data!$T$2:$T$2552,Raw_Data!$B$2:$B$2552,$A43) | E43: =IFERROR(C43/D43,"") | F43: =SUMIFS(Raw_Data!$W$2:$W$2552,Raw_Data!$B$2:$B$2552,$A43) | G43: =IFERROR(F43/C43,"") | H43: =IFERROR(B43/F43,"") | I43: =IFERROR(B43/C43*1000,"") | J43: =SUMIFS(Raw_Data!$AA$2:$AA$2552,Raw_Data!$B$2:$B$2552,$A43) | K43: =IFERROR(J43/F43,"") | L43: =SUMIFS(Raw_Data!$AL$2:$AL$2552,Raw_Data!$B$2:$B$2552,$A43) | M43: =IFERROR(L43/J43,"") | N43: =IFERROR(B43/L43,"") | O43: =SUMIFS(Raw_Data!$AO$2:$AO$2552,Raw_Data!$B$2:$B$2552,$A43) | P43: =IFERROR(O43/L43,"") | Q43: =IFERROR(B43/O43,"") | R43: =SUMIFS(Raw_Data!$AR$2:$AR$2552,Raw_Data!$B$2:$B$2552,$A43) | S43: =SUMIFS(Raw_Data!$AS$2:$AS$2552,Raw_Data!$B$2:$B$2552,$A43) | T43: =L43+R43 | U43: =SUMIFS(Raw_Data!$AU$2:$AU$2552,Raw_Data!$B$2:$B$2552,$A43) | V43: =IFERROR(B43/$B$17,"") | W43: =IFERROR(L43/$L$17,"")
A44: Wk 36 | B44: =SUMIFS(Raw_Data!$R$2:$R$2552,Raw_Data!$B$2:$B$2552,$A44) | C44: =SUMIFS(Raw_Data!$S$2:$S$2552,Raw_Data!$B$2:$B$2552,$A44) | D44: =SUMIFS(Raw_Data!$T$2:$T$2552,Raw_Data!$B$2:$B$2552,$A44) | E44: =IFERROR(C44/D44,"") | F44: =SUMIFS(Raw_Data!$W$2:$W$2552,Raw_Data!$B$2:$B$2552,$A44) | G44: =IFERROR(F44/C44,"") | H44: =IFERROR(B44/F44,"") | I44: =IFERROR(B44/C44*1000,"") | J44: =SUMIFS(Raw_Data!$AA$2:$AA$2552,Raw_Data!$B$2:$B$2552,$A44) | K44: =IFERROR(J44/F44,"") | L44: =SUMIFS(Raw_Data!$AL$2:$AL$2552,Raw_Data!$B$2:$B$2552,$A44) | M44: =IFERROR(L44/J44,"") | N44: =IFERROR(B44/L44,"") | O44: =SUMIFS(Raw_Data!$AO$2:$AO$2552,Raw_Data!$B$2:$B$2552,$A44) | P44: =IFERROR(O44/L44,"") | Q44: =IFERROR(B44/O44,"") | R44: =SUMIFS(Raw_Data!$AR$2:$AR$2552,Raw_Data!$B$2:$B$2552,$A44) | S44: =SUMIFS(Raw_Data!$AS$2:$AS$2552,Raw_Data!$B$2:$B$2552,$A44) | T44: =L44+R44 | U44: =SUMIFS(Raw_Data!$AU$2:$AU$2552,Raw_Data!$B$2:$B$2552,$A44) | V44: =IFERROR(B44/$B$17,"") | W44: =IFERROR(L44/$L$17,"")
A45: TOTAL | E45: =IFERROR(C45/D45,"") | G45: =IFERROR(F45/C45,"") | H45: =IFERROR(B45/F45,"") | I45: =IFERROR(B45/C45*1000,"") | K45: =IFERROR(J45/F45,"") | M45: =IFERROR(L45/J45,"") | N45: =IFERROR(B45/L45,"") | P45: =IFERROR(O45/L45,"") | Q45: =IFERROR(B45/O45,"") | T45: =L45+R45 | V45: =IFERROR(B45/$B$17,"") | W45: =IFERROR(L45/$L$17,"")

Sheet Daily_Trend
A1: Daily Trend — 1 to 31 August 2026
A2: Total market delivery per day, cumulative pacing against the R400,000 plan, and per-channel spend / bookings / CPL for charting.
A4: Date | B4: Day | C4: Week | D4: Spend (ZAR) | E4: Impressions | F4: Reach (sum of daily) | G4: Avg Daily Frequency | H4: Link Clicks | I4: CTR (Link) | J4: CPC (Link) | K4: CPM | L4: Landing Page Views | M4: LPV Rate | N4: Test Drive Bookings | O4: CVR (Booking / LPV) | P4: CPL (Cost / Booking) | Q4: Qualified Leads | R4: Qualified Rate | S4: Cost per Qualified Lead | T4: View-Through Conv. | U4: Assisted Conv. | V4: Total Attributed Conv. | W4: Est. Revenue Pipeline (ZAR) | X4: % of Spend | Y4: % of Bookings | Z4: Cumulative Spend | AA4: Cumulative Bookings | AB4: Cumulative CPL | AC4: Budget Consumed | AD4: Month Elapsed | AE4: Pacing Index | AF4: Meta (FB/IG) Spend | AG4: Meta (FB/IG) Bookings | AH4: Meta (FB/IG) CPL | AI4: TikTok Spend | AJ4: TikTok Bookings | AK4: TikTok CPL | AL4: X Spend | AM4: X Bookings | AN4: X CPL | AO4: Programmatic Spend | AP4: Programmatic Bookings | AQ4: Programmatic CPL
A5: 46235 | B5: Sat | C5: Wk 31 | D5: =SUMIFS(Raw_Data!$R$2:$R$2552,Raw_Data!$A$2:$A$2552,$A5) | E5: =SUMIFS(Raw_Data!$S$2:$S$2552,Raw_Data!$A$2:$A$2552,$A5) | F5: =SUMIFS(Raw_Data!$T$2:$T$2552,Raw_Data!$A$2:$A$2552,$A5) | G5: =IFERROR(E5/F5,"") | H5: =SUMIFS(Raw_Data!$W$2:$W$2552,Raw_Data!$A$2:$A$2552,$A5) | I5: =IFERROR(H5/E5,"") | J5: =IFERROR(D5/H5,"") | K5: =IFERROR(D5/E5*1000,"") | L5: =SUMIFS(Raw_Data!$AA$2:$AA$2552,Raw_Data!$A$2:$A$2552,$A5) | M5: =IFERROR(L5/H5,"") | N5: =SUMIFS(Raw_Data!$AL$2:$AL$2552,Raw_Data!$A$2:$A$2552,$A5) | O5: =IFERROR(N5/L5,"") | P5: =IFERROR(D5/N5,"") | Q5: =SUMIFS(Raw_Data!$AO$2:$AO$2552,Raw_Data!$A$2:$A$2552,$A5) | R5: =IFERROR(Q5/N5,"") | S5: =IFERROR(D5/Q5,"") | T5: =SUMIFS(Raw_Data!$AR$2:$AR$2552,Raw_Data!$A$2:$A$2552,$A5) | U5: =SUMIFS(Raw_Data!$AS$2:$AS$2552,Raw_Data!$A$2:$A$2552,$A5) | V5: =N5+T5 | W5: =SUMIFS(Raw_Data!$AU$2:$AU$2552,Raw_Data!$A$2:$A$2552,$A5) | X5: =IFERROR(D5/$D$36,"") | Y5: =IFERROR(N5/$N$36,"") | Z5: =SUM($D$5:D5) | AA5: =SUM($N$5:N5) | AB5: =IFERROR(Z5/AA5,"") | AC5: =IFERROR(Z5/Assumptions!$C$10,"") | AD5: =1/31 | AE5: =IFERROR(AC5/AD5,"") | AF5: =SUMIFS(Raw_Data!$R$2:$R$2552,Raw_Data!$A$2:$A$2552,$A5,Raw_Data!$D$2:$D$2552,"Meta (FB/IG)") | AG5: =SUMIFS(Raw_Data!$AL$2:$AL$2552,Raw_Data!$A$2:$A$2552,$A5,Raw_Data!$D$2:$D$2552,"Meta (FB/IG)") | AH5: =IFERROR(AF5/AG5,"") | AI5: =SUMIFS(Raw_Data!$R$2:$R$2552,Raw_Data!$A$2:$A$2552,$A5,Raw_Data!$D$2:$D$2552,"TikTok") | AJ5: =SUMIFS(Raw_Data!$AL$2:$AL$2552,Raw_Data!$A$2:$A$2552,$A5,Raw_Data!$D$2:$D$2552,"TikTok") | AK5: =IFERROR(AI5/AJ5,"") | AL5: =SUMIFS(Raw_Data!$R$2:$R$2552,Raw_Data!$A$2:$A$2552,$A5,Raw_Data!$D$2:$D$2552,"X") | AM5: =SUMIFS(Raw_Data!$AL$2:$AL$2552,Raw_Data!$A$2:$A$2552,$A5,Raw_Data!$D$2:$D$2552,"X") | AN5: =IFERROR(AL5/AM5,"") | AO5: =SUMIFS(Raw_Data!$R$2:$R$2552,Raw_Data!$A$2:$A$2552,$A5,Raw_Data!$D$2:$D$2552,"Programmatic") | AP5: =SUMIFS(Raw_Data!$AL$2:$AL$2552,Raw_Data!$A$2:$A$2552,$A5,Raw_Data!$D$2:$D$2552,"Programmatic") | AQ5: =IFERROR(AO5/AP5,"")
A6: 46236 | B6: Sun | C6: Wk 31 | D6: =SUMIFS(Raw_Data!$R$2:$R$2552,Raw_Data!$A$2:$A$2552,$A6) | E6: =SUMIFS(Raw_Data!$S$2:$S$2552,Raw_Data!$A$2:$A$2552,$A6) | F6: =SUMIFS(Raw_Data!$T$2:$T$2552,Raw_Data!$A$2:$A$2552,$A6) | G6: =IFERROR(E6/F6,"") | H6: =SUMIFS(Raw_Data!$W$2:$W$2552,Raw_Data!$A$2:$A$2552,$A6) | I6: =IFERROR(H6/E6,"") | J6: =IFERROR(D6/H6,"") | K6: =IFERROR(D6/E6*1000,"") | L6: =SUMIFS(Raw_Data!$AA$2:$AA$2552,Raw_Data!$A$2:$A$2552,$A6) | M6: =IFERROR(L6/H6,"") | N6: =SUMIFS(Raw_Data!$AL$2:$AL$2552,Raw_Data!$A$2:$A$2552,$A6) | O6: =IFERROR(N6/L6,"") | P6: =IFERROR(D6/N6,"") | Q6: =SUMIFS(Raw_Data!$AO$2:$AO$2552,Raw_Data!$A$2:$A$2552,$A6) | R6: =IFERROR(Q6/N6,"") | S6: =IFERROR(D6/Q6,"") | T6: =SUMIFS(Raw_Data!$AR$2:$AR$2552,Raw_Data!$A$2:$A$2552,$A6) | U6: =SUMIFS(Raw_Data!$AS$2:$AS$2552,Raw_Data!$A$2:$A$2552,$A6) | V6: =N6+T6 | W6: =SUMIFS(Raw_Data!$AU$2:$AU$2552,Raw_Data!$A$2:$A$2552,$A6) | X6: =IFERROR(D6/$D$36,"") | Y6: =IFERROR(N6/$N$36,"") | Z6: =SUM($D$5:D6) | AA6: =SUM($N$5:N6) | AB6: =IFERROR(Z6/AA6,"") | AC6: =IFERROR(Z6/Assumptions!$C$10,"") | AD6: =2/31 | AE6: =IFERROR(AC6/AD6,"") | AF6: =SUMIFS(Raw_Data!$R$2:$R$2552,Raw_Data!$A$2:$A$2552,$A6,Raw_Data!$D$2:$D$2552,"Meta (FB/IG)") | AG6: =SUMIFS(Raw_Data!$AL$2:$AL$2552,Raw_Data!$A$2:$A$2552,$A6,Raw_Data!$D$2:$D$2552,"Meta (FB/IG)") | AH6: =IFERROR(AF6/AG6,"") | AI6: =SUMIFS(Raw_Data!$R$2:$R$2552,Raw_Data!$A$2:$A$2552,$A6,Raw_Data!$D$2:$D$2552,"TikTok") | AJ6: =SUMIFS(Raw_Data!$AL$2:$AL$2552,Raw_Data!$A$2:$A$2552,$A6,Raw_Data!$D$2:$D$2552,"TikTok") | AK6: =IFERROR(AI6/AJ6,"") | AL6: =SUMIFS(Raw_Data!$R$2:$R$2552,Raw_Data!$A$2:$A$2552,$A6,Raw_Data!$D$2:$D$2552,"X") | AM6: =SUMIFS(Raw_Data!$AL$2:$AL$2552,Raw_Data!$A$2:$A$2552,$A6,Raw_Data!$D$2:$D$2552,"X") | AN6: =IFERROR(AL6/AM6,"") | AO6: =SUMIFS(Raw_Data!$R$2:$R$2552,Raw_Data!$A$2:$A$2552,$A6,Raw_Data!$D$2:$D$2552,"Programmatic") | AP6: =SUMIFS(Raw_Data!$AL$2:$AL$2552,Raw_Data!$A$2:$A$2552,$A6,Raw_Data!$D$2:$D$2552,"Programmatic") | AQ6: =IFERROR(AO6/AP6,"")
A7: 46237 | B7: Mon | C7: Wk 32 | D7: =SUMIFS(Raw_Data!$R$2:$R$2552,Raw_Data!$A$2:$A$2552,$A7) | E7: =SUMIFS(Raw_Data!$S$2:$S$2552,Raw_Data!$A$2:$A$2552,$A7) | F7: =SUMIFS(Raw_Data!$T$2:$T$2552,Raw_Data!$A$2:$A$2552,$A7) | G7: =IFERROR(E7/F7,"") | H7: =SUMIFS(Raw_Data!$W$2:$W$2552,Raw_Data!$A$2:$A$2552,$A7) | I7: =IFERROR(H7/E7,"") | J7: =IFERROR(D7/H7,"") | K7: =IFERROR(D7/E7*1000,"") | L7: =SUMIFS(Raw_Data!$AA$2:$AA$2552,Raw_Data!$A$2:$A$2552,$A7) | M7: =IFERROR(L7/H7,"") | N7: =SUMIFS(Raw_Data!$AL$2:$AL$2552,Raw_Data!$A$2:$A$2552,$A7) | O7: =IFERROR(N7/L7,"") | P7: =IFERROR(D7/N7,"") | Q7: =SUMIFS(Raw_Data!$AO$2:$AO$2552,Raw_Data!$A$2:$A$2552,$A7) | R7: =IFERROR(Q7/N7,"") | S7: =IFERROR(D7/Q7,"") | T7: =SUMIFS(Raw_Data!$AR$2:$AR$2552,Raw_Data!$A$2:$A$2552,$A7) | U7: =SUMIFS(Raw_Data!$AS$2:$AS$2552,Raw_Data!$A$2:$A$2552,$A7) | V7: =N7+T7 | W7: =SUMIFS(Raw_Data!$AU$2:$AU$2552,Raw_Data!$A$2:$A$2552,$A7) | X7: =IFERROR(D7/$D$36,"") | Y7: =IFERROR(N7/$N$36,"") | Z7: =SUM($D$5:D7) | AA7: =SUM($N$5:N7) | AB7: =IFERROR(Z7/AA7,"") | AC7: =IFERROR(Z7/Assumptions!$C$10,"") | AD7: =3/31 | AE7: =IFERROR(AC7/AD7,"") | AF7: =SUMIFS(Raw_Data!$R$2:$R$2552,Raw_Data!$A$2:$A$2552,$A7,Raw_Data!$D$2:$D$2552,"Meta (FB/IG)") | AG7: =SUMIFS(Raw_Data!$AL$2:$AL$2552,Raw_Data!$A$2:$A$2552,$A7,Raw_Data!$D$2:$D$2552,"Meta (FB/IG)") | AH7: =IFERROR(AF7/AG7,"") | AI7: =SUMIFS(Raw_Data!$R$2:$R$2552,Raw_Data!$A$2:$A$2552,$A7,Raw_Data!$D$2:$D$2552,"TikTok") | AJ7: =SUMIFS(Raw_Data!$AL$2:$AL$2552,Raw_Data!$A$2:$A$2552,$A7,Raw_Data!$D$2:$D$2552,"TikTok") | AK7: =IFERROR(AI7/AJ7,"") | AL7: =SUMIFS(Raw_Data!$R$2:$R$2552,Raw_Data!$A$2:$A$2552,$A7,Raw_Data!$D$2:$D$2552,"X") | AM7: =SUMIFS(Raw_Data!$AL$2:$AL$2552,Raw_Data!$A$2:$A$2552,$A7,Raw_Data!$D$2:$D$2552,"X") | AN7: =IFERROR(AL7/AM7,"") | AO7: =SUMIFS(Raw_Data!$R$2:$R$2552,Raw_Data!$A$2:$A$2552,$A7,Raw_Data!$D$2:$D$2552,"Programmatic") | AP7: =SUMIFS(Raw_Data!$AL$2:$AL$2552,Raw_Data!$A$2:$A$2552,$A7,Raw_Data!$D$2:$D$2552,"Programmatic") | AQ7: =IFERROR(AO7/AP7,"")
A8: 46238 | B8: Tue | C8: Wk 32 | D8: =SUMIFS(Raw_Data!$R$2:$R$2552,Raw_Data!$A$2:$A$2552,$A8) | E8: =SUMIFS(Raw_Data!$S$2:$S$2552,Raw_Data!$A$2:$A$2552,$A8) | F8: =SUMIFS(Raw_Data!$T$2:$T$2552,Raw_Data!$A$2:$A$2552,$A8) | G8: =IFERROR(E8/F8,"") | H8: =SUMIFS(Raw_Data!$W$2:$W$2552,Raw_Data!$A$2:$A$2552,$A8) | I8: =IFERROR(H8/E8,"") | J8: =IFERROR(D8/H8,"") | K8: =IFERROR(D8/E8*1000,"") | L8: =SUMIFS(Raw_Data!$AA$2:$AA$2552,Raw_Data!$A$2:$A$2552,$A8) | M8: =IFERROR(L8/H8,"") | N8: =SUMIFS(Raw_Data!$AL$2:$AL$2552,Raw_Data!$A$2:$A$2552,$A8) | O8: =IFERROR(N8/L8,"") | P8: =IFERROR(D8/N8,"") | Q8: =SUMIFS(Raw_Data!$AO$2:$AO$2552,Raw_Data!$A$2:$A$2552,$A8) | R8: =IFERROR(Q8/N8,"") | S8: =IFERROR(D8/Q8,"") | T8: =SUMIFS(Raw_Data!$AR$2:$AR$2552,Raw_Data!$A$2:$A$2552,$A8) | U8: =SUMIFS(Raw_Data!$AS$2:$AS$2552,Raw_Data!$A$2:$A$2552,$A8) | V8: =N8+T8 | W8: =SUMIFS(Raw_Data!$AU$2:$AU$2552,Raw_Data!$A$2:$A$2552,$A8) | X8: =IFERROR(D8/$D$36,"") | Y8: =IFERROR(N8/$N$36,"") | Z8: =SUM($D$5:D8) | AA8: =SUM($N$5:N8) | AB8: =IFERROR(Z8/AA8,"") | AC8: =IFERROR(Z8/Assumptions!$C$10,"") | AD8: =4/31 | AE8: =IFERROR(AC8/AD8,"") | AF8: =SUMIFS(Raw_Data!$R$2:$R$2552,Raw_Data!$A$2:$A$2552,$A8,Raw_Data!$D$2:$D$2552,"Meta (FB/IG)") | AG8: =SUMIFS(Raw_Data!$AL$2:$AL$2552,Raw_Data!$A$2:$A$2552,$A8,Raw_Data!$D$2:$D$2552,"Meta (FB/IG)") | AH8: =IFERROR(AF8/AG8,"") | AI8: =SUMIFS(Raw_Data!$R$2:$R$2552,Raw_Data!$A$2:$A$2552,$A8,Raw_Data!$D$2:$D$2552,"TikTok") | AJ8: =SUMIFS(Raw_Data!$AL$2:$AL$2552,Raw_Data!$A$2:$A$2552,$A8,Raw_Data!$D$2:$D$2552,"TikTok") | AK8: =IFERROR(AI8/AJ8,"") | AL8: =SUMIFS(Raw_Data!$R$2:$R$2552,Raw_Data!$A$2:$A$2552,$A8,Raw_Data!$D$2:$D$2552,"X") | AM8: =SUMIFS(Raw_Data!$AL$2:$AL$2552,Raw_Data!$A$2:$A$2552,$A8,Raw_Data!$D$2:$D$2552,"X") | AN8: =IFERROR(AL8/AM8,"") | AO8: =SUMIFS(Raw_Data!$R$2:$R$2552,Raw_Data!$A$2:$A$2552,$A8,Raw_Data!$D$2:$D$2552,"Programmatic") | AP8: =SUMIFS(Raw_Data!$AL$2:$AL$2552,Raw_Data!$A$2:$A$2552,$A8,Raw_Data!$D$2:$D$2552,"Programmatic") | AQ8: =IFERROR(AO8/AP8,"")
A9: 46239 | B9: Wed | C9: Wk 32 | D9: =SUMIFS(Raw_Data!$R$2:$R$2552,Raw_Data!$A$2:$A$2552,$A9) | E9: =SUMIFS(Raw_Data!$S$2:$S$2552,Raw_Data!$A$2:$A$2552,$A9) | F9: =SUMIFS(Raw_Data!$T$2:$T$2552,Raw_Data!$A$2:$A$2552,$A9) | G9: =IFERROR(E9/F9,"") | H9: =SUMIFS(Raw_Data!$W$2:$W$2552,Raw_Data!$A$2:$A$2552,$A9) | I9: =IFERROR(H9/E9,"") | J9: =IFERROR(D9/H9,"") | K9: =IFERROR(D9/E9*1000,"") | L9: =SUMIFS(Raw_Data!$AA$2:$AA$2552,Raw_Data!$A$2:$A$2552,$A9) | M9: =IFERROR(L9/H9,"") | N9: =SUMIFS(Raw_Data!$AL$2:$AL$2552,Raw_Data!$A$2:$A$2552,$A9) | O9: =IFERROR(N9/L9,"") | P9: =IFERROR(D9/N9,"") | Q9: =SUMIFS(Raw_Data!$AO$2:$AO$2552,Raw_Data!$A$2:$A$2552,$A9) | R9: =IFERROR(Q9/N9,"") | S9: =IFERROR(D9/Q9,"") | T9: =SUMIFS(Raw_Data!$AR$2:$AR$2552,Raw_Data!$A$2:$A$2552,$A9) | U9: =SUMIFS(Raw_Data!$AS$2:$AS$2552,Raw_Data!$A$2:$A$2552,$A9) | V9: =N9+T9 | W9: =SUMIFS(Raw_Data!$AU$2:$AU$2552,Raw_Data!$A$2:$A$2552,$A9) | X9: =IFERROR(D9/$D$36,"") | Y9: =IFERROR(N9/$N$36,"") | Z9: =SUM($D$5:D9) | AA9: =SUM($N$5:N9) | AB9: =IFERROR(Z9/AA9,"") | AC9: =IFERROR(Z9/Assumptions!$C$10,"") | AD9: =5/31 | AE9: =IFERROR(AC9/AD9,"") | AF9: =SUMIFS(Raw_Data!$R$2:$R$2552,Raw_Data!$A$2:$A$2552,$A9,Raw_Data!$D$2:$D$2552,"Meta (FB/IG)") | AG9: =SUMIFS(Raw_Data!$AL$2:$AL$2552,Raw_Data!$A$2:$A$2552,$A9,Raw_Data!$D$2:$D$2552,"Meta (FB/IG)") | AH9: =IFERROR(AF9/AG9,"") | AI9: =SUMIFS(Raw_Data!$R$2:$R$2552,Raw_Data!$A$2:$A$2552,$A9,Raw_Data!$D$2:$D$2552,"TikTok") | AJ9: =SUMIFS(Raw_Data!$AL$2:$AL$2552,Raw_Data!$A$2:$A$2552,$A9,Raw_Data!$D$2:$D$2552,"TikTok") | AK9: =IFERROR(AI9/AJ9,"") | AL9: =SUMIFS(Raw_Data!$R$2:$R$2552,Raw_Data!$A$2:$A$2552,$A9,Raw_Data!$D$2:$D$2552,"X") | AM9: =SUMIFS(Raw_Data!$AL$2:$AL$2552,Raw_Data!$A$2:$A$2552,$A9,Raw_Data!$D$2:$D$2552,"X") | AN9: =IFERROR(AL9/AM9,"") | AO9: =SUMIFS(Raw_Data!$R$2:$R$2552,Raw_Data!$A$2:$A$2552,$A9,Raw_Data!$D$2:$D$2552,"Programmatic") | AP9: =SUMIFS(Raw_Data!$AL$2:$AL$2552,Raw_Data!$A$2:$A$2552,$A9,Raw_Data!$D$2:$D$2552,"Programmatic") | AQ9: =IFERROR(AO9/AP9,"")
A10: 46240 | B10: Thu | C10: Wk 32 | D10: =SUMIFS(Raw_Data!$R$2:$R$2552,Raw_Data!$A$2:$A$2552,$A10) | E10: =SUMIFS(Raw_Data!$S$2:$S$2552,Raw_Data!$A$2:$A$2552,$A10) | F10: =SUMIFS(Raw_Data!$T$2:$T$2552,Raw_Data!$A$2:$A$2552,$A10) | G10: =IFERROR(E10/F10,"") | H10: =SUMIFS(Raw_Data!$W$2:$W$2552,Raw_Data!$A$2:$A$2552,$A10) | I10: =IFERROR(H10/E10,"") | J10: =IFERROR(D10/H10,"") | K10: =IFERROR(D10/E10*1000,"") | L10: =SUMIFS(Raw_Data!$AA$2:$AA$2552,Raw_Data!$A$2:$A$2552,$A10) | M10: =IFERROR(L10/H10,"") | N10: =SUMIFS(Raw_Data!$AL$2:$AL$2552,Raw_Data!$A$2:$A$2552,$A10) | O10: =IFERROR(N10/L10,"") | P10: =IFERROR(D10/N10,"") | Q10: =SUMIFS(Raw_Data!$AO$2:$AO$2552,Raw_Data!$A$2:$A$2552,$A10) | R10: =IFERROR(Q10/N10,"") | S10: =IFERROR(D10/Q10,"") | T10: =SUMIFS(Raw_Data!$AR$2:$AR$2552,Raw_Data!$A$2:$A$2552,$A10) | U10: =SUMIFS(Raw_Data!$AS$2:$AS$2552,Raw_Data!$A$2:$A$2552,$A10) | V10: =N10+T10 | W10: =SUMIFS(Raw_Data!$AU$2:$AU$2552,Raw_Data!$A$2:$A$2552,$A10) | X10: =IFERROR(D10/$D$36,"") | Y10: =IFERROR(N10/$N$36,"") | Z10: =SUM($D$5:D10) | AA10: =SUM($N$5:N10) | AB10: =IFERROR(Z10/AA10,"") | AC10: =IFERROR(Z10/Assumptions!$C$10,"") | AD10: =6/31 | AE10: =IFERROR(AC10/AD10,"") | AF10: =SUMIFS(Raw_Data!$R$2:$R$2552,Raw_Data!$A$2:$A$2552,$A10,Raw_Data!$D$2:$D$2552,"Meta (FB/IG)") | AG10: =SUMIFS(Raw_Data!$AL$2:$AL$2552,Raw_Data!$A$2:$A$2552,$A10,Raw_Data!$D$2:$D$2552,"Meta (FB/IG)") | AH10: =IFERROR(AF10/AG10,"") | AI10: =SUMIFS(Raw_Data!$R$2:$R$2552,Raw_Data!$A$2:$A$2552,$A10,Raw_Data!$D$2:$D$2552,"TikTok") | AJ10: =SUMIFS(Raw_Data!$AL$2:$AL$2552,Raw_Data!$A$2:$A$2552,$A10,Raw_Data!$D$2:$D$2552,"TikTok") | AK10: =IFERROR(AI10/AJ10,"") | AL10: =SUMIFS(Raw_Data!$R$2:$R$2552,Raw_Data!$A$2:$A$2552,$A10,Raw_Data!$D$2:$D$2552,"X") | AM10: =SUMIFS(Raw_Data!$AL$2:$AL$2552,Raw_Data!$A$2:$A$2552,$A10,Raw_Data!$D$2:$D$2552,"X") | AN10: =IFERROR(AL10/AM10,"") | AO10: =SUMIFS(Raw_Data!$R$2:$R$2552,Raw_Data!$A$2:$A$2552,$A10,Raw_Data!$D$2:$D$2552,"Programmatic") | AP10: =SUMIFS(Raw_Data!$AL$2:$AL$2552,Raw_Data!$A$2:$A$2552,$A10,Raw_Data!$D$2:$D$2552,"Programmatic") | AQ10: =IFERROR(AO10/AP10,"")
A11: 46241 | B11: Fri | C11: Wk 32 | D11: =SUMIFS(Raw_Data!$R$2:$R$2552,Raw_Data!$A$2:$A$2552,$A11) | E11: =SUMIFS(Raw_Data!$S$2:$S$2552,Raw_Data!$A$2:$A$2552,$A11) | F11: =SUMIFS(Raw_Data!$T$2:$T$2552,Raw_Data!$A$2:$A$2552,$A11) | G11: =IFERROR(E11/F11,"") | H11: =SUMIFS(Raw_Data!$W$2:$W$2552,Raw_Data!$A$2:$A$2552,$A11) | I11: =IFERROR(H11/E11,"") | J11: =IFERROR(D11/H11,"") | K11: =IFERROR(D11/E11*1000,"") | L11: =SUMIFS(Raw_Data!$AA$2:$AA$2552,Raw_Data!$A$2:$A$2552,$A11) | M11: =IFERROR(L11/H11,"") | N11: =SUMIFS(Raw_Data!$AL$2:$AL$2552,Raw_Data!$A$2:$A$2552,$A11) | O11: =IFERROR(N11/L11,"") | P11: =IFERROR(D11/N11,"") | Q11: =SUMIFS(Raw_Data!$AO$2:$AO$2552,Raw_Data!$A$2:$A$2552,$A11) | R11: =IFERROR(Q11/N11,"") | S11: =IFERROR(D11/Q11,"") | T11: =SUMIFS(Raw_Data!$AR$2:$AR$2552,Raw_Data!$A$2:$A$2552,$A11) | U11: =SUMIFS(Raw_Data!$AS$2:$AS$2552,Raw_Data!$A$2:$A$2552,$A11) | V11: =N11+T11 | W11: =SUMIFS(Raw_Data!$AU$2:$AU$2552,Raw_Data!$A$2:$A$2552,$A11) | X11: =IFERROR(D11/$D$36,"") | Y11: =IFERROR(N11/$N$36,"") | Z11: =SUM($D$5:D11) | AA11: =SUM($N$5:N11) | AB11: =IFERROR(Z11/AA11,"") | AC11: =IFERROR(Z11/Assumptions!$C$10,"") | AD11: =7/31 | AE11: =IFERROR(AC11/AD11,"") | AF11: =SUMIFS(Raw_Data!$R$2:$R$2552,Raw_Data!$A$2:$A$2552,$A11,Raw_Data!$D$2:$D$2552,"Meta (FB/IG)") | AG11: =SUMIFS(Raw_Data!$AL$2:$AL$2552,Raw_Data!$A$2:$A$2552,$A11,Raw_Data!$D$2:$D$2552,"Meta (FB/IG)") | AH11: =IFERROR(AF11/AG11,"") | AI11: =SUMIFS(Raw_Data!$R$2:$R$2552,Raw_Data!$A$2:$A$2552,$A11,Raw_Data!$D$2:$D$2552,"TikTok") | AJ11: =SUMIFS(Raw_Data!$AL$2:$AL$2552,Raw_Data!$A$2:$A$2552,$A11,Raw_Data!$D$2:$D$2552,"TikTok") | AK11: =IFERROR(AI11/AJ11,"") | AL11: =SUMIFS(Raw_Data!$R$2:$R$2552,Raw_Data!$A$2:$A$2552,$A11,Raw_Data!$D$2:$D$2552,"X") | AM11: =SUMIFS(Raw_Data!$AL$2:$AL$2552,Raw_Data!$A$2:$A$2552,$A11,Raw_Data!$D$2:$D$2552,"X") | AN11: =IFERROR(AL11/AM11,"") | AO11: =SUMIFS(Raw_Data!$R$2:$R$2552,Raw_Data!$A$2:$A$2552,$A11,Raw_Data!$D$2:$D$2552,"Programmatic") | AP11: =SUMIFS(Raw_Data!$AL$2:$AL$2552,Raw_Data!$A$2:$A$2552,$A11,Raw_Data!$D$2:$D$2552,"Programmatic") | AQ11: =IFERROR(AO11/AP11,"")
A12: 46242 | B12: Sat | C12: Wk 32 | D12: =SUMIFS(Raw_Data!$R$2:$R$2552,Raw_Data!$A$2:$A$2552,$A12) | E12: =SUMIFS(Raw_Data!$S$2:$S$2552,Raw_Data!$A$2:$A$2552,$A12) | F12: =SUMIFS(Raw_Data!$T$2:$T$2552,Raw_Data!$A$2:$A$2552,$A12) | G12: =IFERROR(E12/F12,"") | H12: =SUMIFS(Raw_Data!$W$2:$W$2552,Raw_Data!$A$2:$A$2552,$A12) | I12: =IFERROR(H12/E12,"") | J12: =IFERROR(D12/H12,"") | K12: =IFERROR(D12/E12*1000,"") | L12: =SUMIFS(Raw_Data!$AA$2:$AA$2552,Raw_Data!$A$2:$A$2552,$A12) | M12: =IFERROR(L12/H12,"") | N12: =SUMIFS(Raw_Data!$AL$2:$AL$2552,Raw_Data!$A$2:$A$2552,$A12) | O12: =IFERROR(N12/L12,"") | P12: =IFERROR(D12/N12,"") | Q12: =SUMIFS(Raw_Data!$AO$2:$AO$2552,Raw_Data!$A$2:$A$2552,$A12) | R12: =IFERROR(Q12/N12,"") | S12: =IFERROR(D12/Q12,"") | T12: =SUMIFS(Raw_Data!$AR$2:$AR$2552,Raw_Data!$A$2:$A$2552,$A12) | U12: =SUMIFS(Raw_Data!$AS$2:$AS$2552,Raw_Data!$A$2:$A$2552,$A12) | V12: =N12+T12 | W12: =SUMIFS(Raw_Data!$AU$2:$AU$2552,Raw_Data!$A$2:$A$2552,$A12) | X12: =IFERROR(D12/$D$36,"") | Y12: =IFERROR(N12/$N$36,"") | Z12: =SUM($D$5:D12) | AA12: =SUM($N$5:N12) | AB12: =IFERROR(Z12/AA12,"") | AC12: =IFERROR(Z12/Assumptions!$C$10,"") | AD12: =8/31 | AE12: =IFERROR(AC12/AD12,"") | AF12: =SUMIFS(Raw_Data!$R$2:$R$2552,Raw_Data!$A$2:$A$2552,$A12,Raw_Data!$D$2:$D$2552,"Meta (FB/IG)") | AG12: =SUMIFS(Raw_Data!$AL$2:$AL$2552,Raw_Data!$A$2:$A$2552,$A12,Raw_Data!$D$2:$D$2552,"Meta (FB/IG)") | AH12: =IFERROR(AF12/AG12,"") | AI12: =SUMIFS(Raw_Data!$R$2:$R$2552,Raw_Data!$A$2:$A$2552,$A12,Raw_Data!$D$2:$D$2552,"TikTok") | AJ12: =SUMIFS(Raw_Data!$AL$2:$AL$2552,Raw_Data!$A$2:$A$2552,$A12,Raw_Data!$D$2:$D$2552,"TikTok") | AK12: =IFERROR(AI12/AJ12,"") | AL12: =SUMIFS(Raw_Data!$R$2:$R$2552,Raw_Data!$A$2:$A$2552,$A12,Raw_Data!$D$2:$D$2552,"X") | AM12: =SUMIFS(Raw_Data!$AL$2:$AL$2552,Raw_Data!$A$2:$A$2552,$A12,Raw_Data!$D$2:$D$2552,"X") | AN12: =IFERROR(AL12/AM12,"") | AO12: =SUMIFS(Raw_Data!$R$2:$R$2552,Raw_Data!$A$2:$A$2552,$A12,Raw_Data!$D$2:$D$2552,"Programmatic") | AP12: =SUMIFS(Raw_Data!$AL$2:$AL$2552,Raw_Data!$A$2:$A$2552,$A12,Raw_Data!$D$2:$D$2552,"Programmatic") | AQ12: =IFERROR(AO12/AP12,"")
A13: 46243 | B13: Sun | C13: Wk 32 | D13: =SUMIFS(Raw_Data!$R$2:$R$2552,Raw_Data!$A$2:$A$2552,$A13) | E13: =SUMIFS(Raw_Data!$S$2:$S$2552,Raw_Data!$A$2:$A$2552,$A13) | F13: =SUMIFS(Raw_Data!$T$2:$T$2552,Raw_Data!$A$2:$A$2552,$A13) | G13: =IFERROR(E13/F13,"") | H13: =SUMIFS(Raw_Data!$W$2:$W$2552,Raw_Data!$A$2:$A$2552,$A13) | I13: =IFERROR(H13/E13,"") | J13: =IFERROR(D13/H13,"") | K13: =IFERROR(D13/E13*1000,"") | L13: =SUMIFS(Raw_Data!$AA$2:$AA$2552,Raw_Data!$A$2:$A$2552,$A13) | M13: =IFERROR(L13/H13,"") | N13: =SUMIFS(Raw_Data!$AL$2:$AL$2552,Raw_Data!$A$2:$A$2552,$A13) | O13: =IFERROR(N13/L13,"") | P13: =IFERROR(D13/N13,"") | Q13: =SUMIFS(Raw_Data!$AO$2:$AO$2552,Raw_Data!$A$2:$A$2552,$A13) | R13: =IFERROR(Q13/N13,"") | S13: =IFERROR(D13/Q13,"") | T13: =SUMIFS(Raw_Data!$AR$2:$AR$2552,Raw_Data!$A$2:$A$2552,$A13) | U13: =SUMIFS(Raw_Data!$AS$2:$AS$2552,Raw_Data!$A$2:$A$2552,$A13) | V13: =N13+T13 | W13: =SUMIFS(Raw_Data!$AU$2:$AU$2552,Raw_Data!$A$2:$A$2552,$A13) | X13: =IFERROR(D13/$D$36,"") | Y13: =IFERROR(N13/$N$36,"") | Z13: =SUM($D$5:D13) | AA13: =SUM($N$5:N13) | AB13: =IFERROR(Z13/AA13,"") | AC13: =IFERROR(Z13/Assumptions!$C$10,"") | AD13: =9/31 | AE13: =IFERROR(AC13/AD13,"") | AF13: =SUMIFS(Raw_Data!$R$2:$R$2552,Raw_Data!$A$2:$A$2552,$A13,Raw_Data!$D$2:$D$2552,"Meta (FB/IG)") | AG13: =SUMIFS(Raw_Data!$AL$2:$AL$2552,Raw_Data!$A$2:$A$2552,$A13,Raw_Data!$D$2:$D$2552,"Meta (FB/IG)") | AH13: =IFERROR(AF13/AG13,"") | AI13: =SUMIFS(Raw_Data!$R$2:$R$2552,Raw_Data!$A$2:$A$2552,$A13,Raw_Data!$D$2:$D$2552,"TikTok") | AJ13: =SUMIFS(Raw_Data!$AL$2:$AL$2552,Raw_Data!$A$2:$A$2552,$A13,Raw_Data!$D$2:$D$2552,"TikTok") | AK13: =IFERROR(AI13/AJ13,"") | AL13: =SUMIFS(Raw_Data!$R$2:$R$2552,Raw_Data!$A$2:$A$2552,$A13,Raw_Data!$D$2:$D$2552,"X") | AM13: =SUMIFS(Raw_Data!$AL$2:$AL$2552,Raw_Data!$A$2:$A$2552,$A13,Raw_Data!$D$2:$D$2552,"X") | AN13: =IFERROR(AL13/AM13,"") | AO13: =SUMIFS(Raw_Data!$R$2:$R$2552,Raw_Data!$A$2:$A$2552,$A13,Raw_Data!$D$2:$D$2552,"Programmatic") | AP13: =SUMIFS(Raw_Data!$AL$2:$AL$2552,Raw_Data!$A$2:$A$2552,$A13,Raw_Data!$D$2:$D$2552,"Programmatic") | AQ13: =IFERROR(AO13/AP13,"")
A14: 46244 | B14: Mon | C14: Wk 33 | D14: =SUMIFS(Raw_Data!$R$2:$R$2552,Raw_Data!$A$2:$A$2552,$A14) | E14: =SUMIFS(Raw_Data!$S$2:$S$2552,Raw_Data!$A$2:$A$2552,$A14) | F14: =SUMIFS(Raw_Data!$T$2:$T$2552,Raw_Data!$A$2:$A$2552,$A14) | G14: =IFERROR(E14/F14,"") | H14: =SUMIFS(Raw_Data!$W$2:$W$2552,Raw_Data!$A$2:$A$2552,$A14) | I14: =IFERROR(H14/E14,"") | J14: =IFERROR(D14/H14,"") | K14: =IFERROR(D14/E14*1000,"") | L14: =SUMIFS(Raw_Data!$AA$2:$AA$2552,Raw_Data!$A$2:$A$2552,$A14) | M14: =IFERROR(L14/H14,"") | N14: =SUMIFS(Raw_Data!$AL$2:$AL$2552,Raw_Data!$A$2:$A$2552,$A14) | O14: =IFERROR(N14/L14,"") | P14: =IFERROR(D14/N14,"") | Q14: =SUMIFS(Raw_Data!$AO$2:$AO$2552,Raw_Data!$A$2:$A$2552,$A14) | R14: =IFERROR(Q14/N14,"") | S14: =IFERROR(D14/Q14,"") | T14: =SUMIFS(Raw_Data!$AR$2:$AR$2552,Raw_Data!$A$2:$A$2552,$A14) | U14: =SUMIFS(Raw_Data!$AS$2:$AS$2552,Raw_Data!$A$2:$A$2552,$A14) | V14: =N14+T14 | W14: =SUMIFS(Raw_Data!$AU$2:$AU$2552,Raw_Data!$A$2:$A$2552,$A14) | X14: =IFERROR(D14/$D$36,"") | Y14: =IFERROR(N14/$N$36,"") | Z14: =SUM($D$5:D14) | AA14: =SUM($N$5:N14) | AB14: =IFERROR(Z14/AA14,"") | AC14: =IFERROR(Z14/Assumptions!$C$10,"") | AD14: =10/31 | AE14: =IFERROR(AC14/AD14,"") | AF14: =SUMIFS(Raw_Data!$R$2:$R$2552,Raw_Data!$A$2:$A$2552,$A14,Raw_Data!$D$2:$D$2552,"Meta (FB/IG)") | AG14: =SUMIFS(Raw_Data!$AL$2:$AL$2552,Raw_Data!$A$2:$A$2552,$A14,Raw_Data!$D$2:$D$2552,"Meta (FB/IG)") | AH14: =IFERROR(AF14/AG14,"") | AI14: =SUMIFS(Raw_Data!$R$2:$R$2552,Raw_Data!$A$2:$A$2552,$A14,Raw_Data!$D$2:$D$2552,"TikTok") | AJ14: =SUMIFS(Raw_Data!$AL$2:$AL$2552,Raw_Data!$A$2:$A$2552,$A14,Raw_Data!$D$2:$D$2552,"TikTok") | AK14: =IFERROR(AI14/AJ14,"") | AL14: =SUMIFS(Raw_Data!$R$2:$R$2552,Raw_Data!$A$2:$A$2552,$A14,Raw_Data!$D$2:$D$2552,"X") | AM14: =SUMIFS(Raw_Data!$AL$2:$AL$2552,Raw_Data!$A$2:$A$2552,$A14,Raw_Data!$D$2:$D$2552,"X") | AN14: =IFERROR(AL14/AM14,"") | AO14: =SUMIFS(Raw_Data!$R$2:$R$2552,Raw_Data!$A$2:$A$2552,$A14,Raw_Data!$D$2:$D$2552,"Programmatic") | AP14: =SUMIFS(Raw_Data!$AL$2:$AL$2552,Raw_Data!$A$2:$A$2552,$A14,Raw_Data!$D$2:$D$2552,"Programmatic") | AQ14: =IFERROR(AO14/AP14,"")
A15: 46245 | B15: Tue | C15: Wk 33 | D15: =SUMIFS(Raw_Data!$R$2:$R$2552,Raw_Data!$A$2:$A$2552,$A15) | E15: =SUMIFS(Raw_Data!$S$2:$S$2552,Raw_Data!$A$2:$A$2552,$A15) | F15: =SUMIFS(Raw_Data!$T$2:$T$2552,Raw_Data!$A$2:$A$2552,$A15) | G15: =IFERROR(E15/F15,"") | H15: =SUMIFS(Raw_Data!$W$2:$W$2552,Raw_Data!$A$2:$A$2552,$A15) | I15: =IFERROR(H15/E15,"") | J15: =IFERROR(D15/H15,"") | K15: =IFERROR(D15/E15*1000,"") | L15: =SUMIFS(Raw_Data!$AA$2:$AA$2552,Raw_Data!$A$2:$A$2552,$A15) | M15: =IFERROR(L15/H15,"") | N15: =SUMIFS(Raw_Data!$AL$2:$AL$2552,Raw_Data!$A$2:$A$2552,$A15) | O15: =IFERROR(N15/L15,"") | P15: =IFERROR(D15/N15,"") | Q15: =SUMIFS(Raw_Data!$AO$2:$AO$2552,Raw_Data!$A$2:$A$2552,$A15) | R15: =IFERROR(Q15/N15,"") | S15: =IFERROR(D15/Q15,"") | T15: =SUMIFS(Raw_Data!$AR$2:$AR$2552,Raw_Data!$A$2:$A$2552,$A15) | U15: =SUMIFS(Raw_Data!$AS$2:$AS$2552,Raw_Data!$A$2:$A$2552,$A15) | V15: =N15+T15 | W15: =SUMIFS(Raw_Data!$AU$2:$AU$2552,Raw_Data!$A$2:$A$2552,$A15) | X15: =IFERROR(D15/$D$36,"") | Y15: =IFERROR(N15/$N$36,"") | Z15: =SUM($D$5:D15) | AA15: =SUM($N$5:N15) | AB15: =IFERROR(Z15/AA15,"") | AC15: =IFERROR(Z15/Assumptions!$C$10,"") | AD15: =11/31 | AE15: =IFERROR(AC15/AD15,"") | AF15: =SUMIFS(Raw_Data!$R$2:$R$2552,Raw_Data!$A$2:$A$2552,$A15,Raw_Data!$D$2:$D$2552,"Meta (FB/IG)") | AG15: =SUMIFS(Raw_Data!$AL$2:$AL$2552,Raw_Data!$A$2:$A$2552,$A15,Raw_Data!$D$2:$D$2552,"Meta (FB/IG)") | AH15: =IFERROR(AF15/AG15,"") | AI15: =SUMIFS(Raw_Data!$R$2:$R$2552,Raw_Data!$A$2:$A$2552,$A15,Raw_Data!$D$2:$D$2552,"TikTok") | AJ15: =SUMIFS(Raw_Data!$AL$2:$AL$2552,Raw_Data!$A$2:$A$2552,$A15,Raw_Data!$D$2:$D$2552,"TikTok") | AK15: =IFERROR(AI15/AJ15,"") | AL15: =SUMIFS(Raw_Data!$R$2:$R$2552,Raw_Data!$A$2:$A$2552,$A15,Raw_Data!$D$2:$D$2552,"X") | AM15: =SUMIFS(Raw_Data!$AL$2:$AL$2552,Raw_Data!$A$2:$A$2552,$A15,Raw_Data!$D$2:$D$2552,"X") | AN15: =IFERROR(AL15/AM15,"") | AO15: =SUMIFS(Raw_Data!$R$2:$R$2552,Raw_Data!$A$2:$A$2552,$A15,Raw_Data!$D$2:$D$2552,"Programmatic") | AP15: =SUMIFS(Raw_Data!$AL$2:$AL$2552,Raw_Data!$A$2:$A$2552,$A15,Raw_Data!$D$2:$D$2552,"Programmatic") | AQ15: =IFERROR(AO15/AP15,"")
A16: 46246 | B16: Wed | C16: Wk 33 | D16: =SUMIFS(Raw_Data!$R$2:$R$2552,Raw_Data!$A$2:$A$2552,$A16) | E16: =SUMIFS(Raw_Data!$S$2:$S$2552,Raw_Data!$A$2:$A$2552,$A16) | F16: =SUMIFS(Raw_Data!$T$2:$T$2552,Raw_Data!$A$2:$A$2552,$A16) | G16: =IFERROR(E16/F16,"") | H16: =SUMIFS(Raw_Data!$W$2:$W$2552,Raw_Data!$A$2:$A$2552,$A16) | I16: =IFERROR(H16/E16,"") | J16: =IFERROR(D16/H16,"") | K16: =IFERROR(D16/E16*1000,"") | L16: =SUMIFS(Raw_Data!$AA$2:$AA$2552,Raw_Data!$A$2:$A$2552,$A16) | M16: =IFERROR(L16/H16,"") | N16: =SUMIFS(Raw_Data!$AL$2:$AL$2552,Raw_Data!$A$2:$A$2552,$A16) | O16: =IFERROR(N16/L16,"") | P16: =IFERROR(D16/N16,"") | Q16: =SUMIFS(Raw_Data!$AO$2:$AO$2552,Raw_Data!$A$2:$A$2552,$A16) | R16: =IFERROR(Q16/N16,"") | S16: =IFERROR(D16/Q16,"") | T16: =SUMIFS(Raw_Data!$AR$2:$AR$2552,Raw_Data!$A$2:$A$2552,$A16) | U16: =SUMIFS(Raw_Data!$AS$2:$AS$2552,Raw_Data!$A$2:$A$2552,$A16) | V16: =N16+T16 | W16: =SUMIFS(Raw_Data!$AU$2:$AU$2552,Raw_Data!$A$2:$A$2552,$A16) | X16: =IFERROR(D16/$D$36,"") | Y16: =IFERROR(N16/$N$36,"") | Z16: =SUM($D$5:D16) | AA16: =SUM($N$5:N16) | AB16: =IFERROR(Z16/AA16,"") | AC16: =IFERROR(Z16/Assumptions!$C$10,"") | AD16: =12/31 | AE16: =IFERROR(AC16/AD16,"") | AF16: =SUMIFS(Raw_Data!$R$2:$R$2552,Raw_Data!$A$2:$A$2552,$A16,Raw_Data!$D$2:$D$2552,"Meta (FB/IG)") | AG16: =SUMIFS(Raw_Data!$AL$2:$AL$2552,Raw_Data!$A$2:$A$2552,$A16,Raw_Data!$D$2:$D$2552,"Meta (FB/IG)") | AH16: =IFERROR(AF16/AG16,"") | AI16: =SUMIFS(Raw_Data!$R$2:$R$2552,Raw_Data!$A$2:$A$2552,$A16,Raw_Data!$D$2:$D$2552,"TikTok") | AJ16: =SUMIFS(Raw_Data!$AL$2:$AL$2552,Raw_Data!$A$2:$A$2552,$A16,Raw_Data!$D$2:$D$2552,"TikTok") | AK16: =IFERROR(AI16/AJ16,"") | AL16: =SUMIFS(Raw_Data!$R$2:$R$2552,Raw_Data!$A$2:$A$2552,$A16,Raw_Data!$D$2:$D$2552,"X") | AM16: =SUMIFS(Raw_Data!$AL$2:$AL$2552,Raw_Data!$A$2:$A$2552,$A16,Raw_Data!$D$2:$D$2552,"X") | AN16: =IFERROR(AL16/AM16,"") | AO16: =SUMIFS(Raw_Data!$R$2:$R$2552,Raw_Data!$A$2:$A$2552,$A16,Raw_Data!$D$2:$D$2552,"Programmatic") | AP16: =SUMIFS(Raw_Data!$AL$2:$AL$2552,Raw_Data!$A$2:$A$2552,$A16,Raw_Data!$D$2:$D$2552,"Programmatic") | AQ16: =IFERROR(AO16/AP16,"")
A17: 46247 | B17: Thu | C17: Wk 33 | D17: =SUMIFS(Raw_Data!$R$2:$R$2552,Raw_Data!$A$2:$A$2552,$A17) | E17: =SUMIFS(Raw_Data!$S$2:$S$2552,Raw_Data!$A$2:$A$2552,$A17) | F17: =SUMIFS(Raw_Data!$T$2:$T$2552,Raw_Data!$A$2:$A$2552,$A17) | G17: =IFERROR(E17/F17,"") | H17: =SUMIFS(Raw_Data!$W$2:$W$2552,Raw_Data!$A$2:$A$2552,$A17) | I17: =IFERROR(H17/E17,"") | J17: =IFERROR(D17/H17,"") | K17: =IFERROR(D17/E17*1000,"") | L17: =SUMIFS(Raw_Data!$AA$2:$AA$2552,Raw_Data!$A$2:$A$2552,$A17) | M17: =IFERROR(L17/H17,"") | N17: =SUMIFS(Raw_Data!$AL$2:$AL$2552,Raw_Data!$A$2:$A$2552,$A17) | O17: =IFERROR(N17/L17,"") | P17: =IFERROR(D17/N17,"") | Q17: =SUMIFS(Raw_Data!$AO$2:$AO$2552,Raw_Data!$A$2:$A$2552,$A17) | R17: =IFERROR(Q17/N17,"") | S17: =IFERROR(D17/Q17,"") | T17: =SUMIFS(Raw_Data!$AR$2:$AR$2552,Raw_Data!$A$2:$A$2552,$A17) | U17: =SUMIFS(Raw_Data!$AS$2:$AS$2552,Raw_Data!$A$2:$A$2552,$A17) | V17: =N17+T17 | W17: =SUMIFS(Raw_Data!$AU$2:$AU$2552,Raw_Data!$A$2:$A$2552,$A17) | X17: =IFERROR(D17/$D$36,"") | Y17: =IFERROR(N17/$N$36,"") | Z17: =SUM($D$5:D17) | AA17: =SUM($N$5:N17) | AB17: =IFERROR(Z17/AA17,"") | AC17: =IFERROR(Z17/Assumptions!$C$10,"") | AD17: =13/31 | AE17: =IFERROR(AC17/AD17,"") | AF17: =SUMIFS(Raw_Data!$R$2:$R$2552,Raw_Data!$A$2:$A$2552,$A17,Raw_Data!$D$2:$D$2552,"Meta (FB/IG)") | AG17: =SUMIFS(Raw_Data!$AL$2:$AL$2552,Raw_Data!$A$2:$A$2552,$A17,Raw_Data!$D$2:$D$2552,"Meta (FB/IG)") | AH17: =IFERROR(AF17/AG17,"") | AI17: =SUMIFS(Raw_Data!$R$2:$R$2552,Raw_Data!$A$2:$A$2552,$A17,Raw_Data!$D$2:$D$2552,"TikTok") | AJ17: =SUMIFS(Raw_Data!$AL$2:$AL$2552,Raw_Data!$A$2:$A$2552,$A17,Raw_Data!$D$2:$D$2552,"TikTok") | AK17: =IFERROR(AI17/AJ17,"") | AL17: =SUMIFS(Raw_Data!$R$2:$R$2552,Raw_Data!$A$2:$A$2552,$A17,Raw_Data!$D$2:$D$2552,"X") | AM17: =SUMIFS(Raw_Data!$AL$2:$AL$2552,Raw_Data!$A$2:$A$2552,$A17,Raw_Data!$D$2:$D$2552,"X") | AN17: =IFERROR(AL17/AM17,"") | AO17: =SUMIFS(Raw_Data!$R$2:$R$2552,Raw_Data!$A$2:$A$2552,$A17,Raw_Data!$D$2:$D$2552,"Programmatic") | AP17: =SUMIFS(Raw_Data!$AL$2:$AL$2552,Raw_Data!$A$2:$A$2552,$A17,Raw_Data!$D$2:$D$2552,"Programmatic") | AQ17: =IFERROR(AO17/AP17,"")
A18: 46248 | B18: Fri | C18: Wk 33 | D18: =SUMIFS(Raw_Data!$R$2:$R$2552,Raw_Data!$A$2:$A$2552,$A18) | E18: =SUMIFS(Raw_Data!$S$2:$S$2552,Raw_Data!$A$2:$A$2552,$A18) | F18: =SUMIFS(Raw_Data!$T$2:$T$2552,Raw_Data!$A$2:$A$2552,$A18) | G18: =IFERROR(E18/F18,"") | H18: =SUMIFS(Raw_Data!$W$2:$W$2552,Raw_Data!$A$2:$A$2552,$A18) | I18: =IFERROR(H18/E18,"") | J18: =IFERROR(D18/H18,"") | K18: =IFERROR(D18/E18*1000,"") | L18: =SUMIFS(Raw_Data!$AA$2:$AA$2552,Raw_Data!$A$2:$A$2552,$A18) | M18: =IFERROR(L18/H18,"") | N18: =SUMIFS(Raw_Data!$AL$2:$AL$2552,Raw_Data!$A$2:$A$2552,$A18) | O18: =IFERROR(N18/L18,"") | P18: =IFERROR(D18/N18,"") | Q18: =SUMIFS(Raw_Data!$AO$2:$AO$2552,Raw_Data!$A$2:$A$2552,$A18) | R18: =IFERROR(Q18/N18,"") | S18: =IFERROR(D18/Q18,"") | T18: =SUMIFS(Raw_Data!$AR$2:$AR$2552,Raw_Data!$A$2:$A$2552,$A18) | U18: =SUMIFS(Raw_Data!$AS$2:$AS$2552,Raw_Data!$A$2:$A$2552,$A18) | V18: =N18+T18 | W18: =SUMIFS(Raw_Data!$AU$2:$AU$2552,Raw_Data!$A$2:$A$2552,$A18) | X18: =IFERROR(D18/$D$36,"") | Y18: =IFERROR(N18/$N$36,"") | Z18: =SUM($D$5:D18) | AA18: =SUM($N$5:N18) | AB18: =IFERROR(Z18/AA18,"") | AC18: =IFERROR(Z18/Assumptions!$C$10,"") | AD18: =14/31 | AE18: =IFERROR(AC18/AD18,"") | AF18: =SUMIFS(Raw_Data!$R$2:$R$2552,Raw_Data!$A$2:$A$2552,$A18,Raw_Data!$D$2:$D$2552,"Meta (FB/IG)") | AG18: =SUMIFS(Raw_Data!$AL$2:$AL$2552,Raw_Data!$A$2:$A$2552,$A18,Raw_Data!$D$2:$D$2552,"Meta (FB/IG)") | AH18: =IFERROR(AF18/AG18,"") | AI18: =SUMIFS(Raw_Data!$R$2:$R$2552,Raw_Data!$A$2:$A$2552,$A18,Raw_Data!$D$2:$D$2552,"TikTok") | AJ18: =SUMIFS(Raw_Data!$AL$2:$AL$2552,Raw_Data!$A$2:$A$2552,$A18,Raw_Data!$D$2:$D$2552,"TikTok") | AK18: =IFERROR(AI18/AJ18,"") | AL18: =SUMIFS(Raw_Data!$R$2:$R$2552,Raw_Data!$A$2:$A$2552,$A18,Raw_Data!$D$2:$D$2552,"X") | AM18: =SUMIFS(Raw_Data!$AL$2:$AL$2552,Raw_Data!$A$2:$A$2552,$A18,Raw_Data!$D$2:$D$2552,"X") | AN18: =IFERROR(AL18/AM18,"") | AO18: =SUMIFS(Raw_Data!$R$2:$R$2552,Raw_Data!$A$2:$A$2552,$A18,Raw_Data!$D$2:$D$2552,"Programmatic") | AP18: =SUMIFS(Raw_Data!$AL$2:$AL$2552,Raw_Data!$A$2:$A$2552,$A18,Raw_Data!$D$2:$D$2552,"Programmatic") | AQ18: =IFERROR(AO18/AP18,"")
